Workbook

Sheet Mastersheet
A1: player_id | B1: player | C1: role | D1: is_batsman_1 | E1: is_bowler_1 | F1: is_allrounder_1 | G1: is_wicket_keeper_1 | H1: innings | I1: matches | J1: runs_normalised | K1: runs | L1: batting_impact | M1: bowling_impact | N1: batting_position | O1: batting_positions | P1: nationality | Q1: nationality_enc | R1: age | S1: high_score | T1: batting_average | U1: batting_avg_normalization | V1: strike_rate | W1: strike_rate_norm | X1: 4s | Y1: 6s | Z1: 100s | AA1: 50s | AB1: auction_price_cr | AC1: price_flag | AD1: base_price_cr | AE1: approximate_big_match_index | AF1: approximate_big_match_index_norm | AG1: vfm | AH1: vfm_norm | AI1: consistency_score | AJ1: consistency_score_norm | AK1: wickets | AL1: overs_bowled | AM1: economy_rate | AN1: economy_rate_norm | AO1: death_over_economy_norm | AP1: death_over_economy_rate | AQ1: risk_rate_norm | AR1: risk_rating | AS1: approximate_wickets_per_match | AT1: approximate_wickets_per_match_norm | AU1: dot_ball_percentage | AV1: dot_ball_percentage_norm | AW1: bat_percentage | AX1: bat_percentage_normalized | AY1: total_dismissals | AZ1: total_dismissal_normalized | BA1: stump_percentage | BB1: stump_percentage_normalized | BC1: bowl_percentage | BD1: bowling_avg | BE1: recent_form_score | BF1: recent_form_score_norm | BG1: player_category | BH1: last_season_performance | BI1: last_season_performance_norm | BJ1: performance_vs_spin | BK1: performance_vs_spin_norm | BL1: performance_vs_pace | BM1: performance_vs_pace_norm | BN1: allrounder_score | BO1: wicket_keeper_score | BP1: batsmen_score | BQ1: bowler_score | BR1: venue_impact_score_hm | BS1: away_impact_score_hm | BT1: select_player | BU1: BU | BV1: player_score | BW1: player_score_normalised | BX1: batting_fantasy_score | BY1: bowler_fantasy_score | BZ1: all_rounder_fantasy_score | CA1: wicket_keeper_fantasy_score | CB1: base_fantasy_points | CC1: venue_mul | CD1: venue_fp | CE1: risk_mul | CF1: predicted_fantasy_points | CG1: rank
A2: 1070173 | B2: Shubman Gill | C2: Batsman | D2: 1 | E2: 0 | F2: 0 | G2: 0 | H2: 30 | I2: 30 | J2: =ROUND((K2 - MIN($K$2:$K$98)) / (MAX($K$2:$K$98) - MIN($K$2:$K$98)), 1) -> 1 | K2: 1361 | L2: 1 | M2: 0 | N2: Opener | O2: 1 | P2: India | Q2: 0 | R2: 24 | S2: 129 | T2: 52.35 | U2: =ROUND((T2 - MIN(T$2:T$98)) / (MAX(T$2:T$98) - MIN(T$2:T$98)), 1) -> 0.9 | V2: 151.9 | W2: =ROUND((V2 - MIN(V$2:V$98)) / (MAX(V$2:V$98) - MIN(V$2:V$98)), 1) -> 0.6 | X2: 125 | Y2: 49 | Z2: 4 | AA2: 6 | AB2: 16.5 | AC2: =IF(AB2>AD2, 3,IF(AB2<AD2, 1, 2)) -> 3 | AD2: 0 | AE2: 0.7 | AF2: 0.0175 | AG2: 8.5 | AH2: 0.013 | AI2: 80 | AJ2: =ROUND((AI2 - MIN(AI$2:AI$98)) / (MAX(AI$2:AI$98) - MIN(AI$2:AI$98)), 1) -> 0.9 | AK2: 0 | AL2: 0 | AM2: 0 | AN2: 0 | AO2: =ROUND((AP2 - MIN($AP$2:$AP2050)) / (MAX($AP$2:$AP2050) - MIN($AP$2:$AP2050)), 1) -> 0 | AP2: 0 | AQ2: =ROUND((AR2 - MIN($AR$2:$AR2050)) / (MAX($AR$2:$AR2050) - MIN($AR$2:$AR2050)), 1) -> 0.3 | AR2: 3.5 | AS2: 0 | AT2: 0 | AU2: 0 | AV2: 0 | AW2: 50 | AX2: 0.5 | AY2: 0 | AZ2: =(AP2 - MIN($AP$2:$AP$964)) / (MAX($AP$2:$AP$964) - MIN($AP$2:$AP$964)) -> 0 | BA2: 0 | BB2: 0 | BC2: 0 | BD2: 0 | BE2: 9 | BF2: =ROUND((BE2 - MIN(BE$2:BE$174)) / (MAX(BE$2:BE$174) - MIN(BE$2:BE$174)), 1) -> 0.8 | BG2: =IF(AND(K2>=800,V2>=145),3,IF(K2>=400,1,2)) -> 3 | BH2: 9 | BI2: =ROUND((BH2 - MIN(BH$2:BH$174)) / (MAX(BH$2:BH$174) - MIN(BH$2:BH$174)), 1) -> 1 | BJ2: 8 | BK2: 0.86 | BL2: 8 | BM2: 0.67 | BN2: 0 | BO2: 0 | BP2: =ROUND((0.35 * L2) + (0.25 * W2) + (0.15 * U2) + (0.15 * BF2) + (0.1 * AJ2), 1) -> 0.8 | BQ2: 0 | BR2: 0.78 | BS2: =(0.45*L2 + 0.35*M2 + 0.12*AJ2 + 0.08*BF2) * (1 - BR2) -> 0.13684 | BT2: 0 | BU2: 0 | BV2: 67.2 | BW2: 0.078 | BX2: =D2 * ( BP2*0.4 + L2*0.25 + W2*0.15 + AX2*0.1 + BF2*0.1 ) * 100 -> 79 | BY2: =E:E*(BQ:BQ*0.35+AT:AT*0.3+AV:AV*0.15+AN:AN*0.1+AO:AO*0.1)*100 -> 0 | BZ2: =ROUND(IF(N(F2)=1, MAX(0, ( (N(BN2)/18)*0.6 + (N(BF2)/10)*0.25 + N(AX2)*0.15 ) * 100 ), 0 ),3) -> 0 | CA2: =ROUND(G:G*(BO:BO*0.45+AZ:AZ*0.3+BB:BB*0.15+BF:BF*0.1)*100,3) -> 0 | CB2: =BX:BX+BY:BY+BZ:BZ + CA:CA -> 79 | CC2: =ROUND(0.7 + (BR:BR* 0.2) + (BS:BS * 0.1),3) -> 0.87 | CD2: =ROUND(CB:CB* CC:CC, 2) -> 68.73 | CE2: =ROUND( 1 - ( (D:D * 0.25) + (E:E* 0.2) + (F:F* 0.15) + (G:G* 0.1) ) * AQ:AQ, 3 ) -> 0.925 | CF2: =ROUND( CD:CD* CE:CE, 2 ) -> 63.58 | CG2: =RANK(CF2,CF:CF) -> 18
A3: 446507 | B3: Surya Kumar Yadav | C3: Batsman | D3: 1 | E3: 0 | F3: 0 | G3: 0 | H3: 27 | I3: 27 | J3: =ROUND((K3 - MIN($K$2:$K$98)) / (MAX($K$2:$K$98) - MIN($K$2:$K$98)), 1) -> 0.7 | K3: 950 | L3: 0.6 | M3: 0 | N3: Middle | O3: 2 | P3: India | Q3: 0 | R3: 33 | S3: 103 | T3: 39.58 | U3: =ROUND((T3 - MIN(T$2:T$98)) / (MAX(T$2:T$98) - MIN(T$2:T$98)), 1) -> 0.7 | V3: 175.93 | W3: =ROUND((V3 - MIN(V$2:V$98)) / (MAX(V$2:V$98) - MIN(V$2:V$98)), 1) -> 0.7 | X3: 101 | Y3: 46 | Z3: 2 | AA3: 8 | AB3: =SUBSTITUTE(AB2, "Cr", "") -> 16.5 | AC3: =IF(AB3>AD3, 3,IF(AB3<AD3, 1, 2)) -> 3 | AD3: 0 | AE3: 0.7 | AF3: 0.0175 | AG3: 9 | AH3: 0.222 | AI3: 70 | AJ3: =ROUND((AI3 - MIN(AI$2:AI$98)) / (MAX(AI$2:AI$98) - MIN(AI$2:AI$98)), 1) -> 0.8 | AK3: 0 | AL3: 0 | AM3: 0 | AN3: 0 | AO3: =ROUND((AP3 - MIN($AP$2:$AP2051)) / (MAX($AP$2:$AP2051) - MIN($AP$2:$AP2051)), 1) -> 0 | AP3: 0 | AQ3: =ROUND((AR3 - MIN($AR$2:$AR2051)) / (MAX($AR$2:$AR2051) - MIN($AR$2:$AR2051)), 1) -> 0.5 | AR3: 5 | AS3: 0 | AT3: 0 | AU3: 0 | AV3: 0 | AW3: 65 | AX3: 0.7 | AY3: 0 | AZ3: =(AP3 - MIN($AP$2:$AP$964)) / (MAX($AP$2:$AP$964) - MIN($AP$2:$AP$964)) -> 0 | BA3: 0 | BB3: 0 | BC3: 0 | BD3: 0 | BE3: 9.5 | BF3: =ROUND((BE3 - MIN(BE$2:BE$174)) / (MAX(BE$2:BE$174) - MIN(BE$2:BE$174)), 1) -> 0.9 | BG3: =IF(AND(K3>=800,V3>=145),3,IF(K3>=400,1,2)) -> 3 | BH3: 8 | BI3: =ROUND((BH3 - MIN(BH$2:BH$174)) / (MAX(BH$2:BH$174) - MIN(BH$2:BH$174)), 1) -> 0.7 | BJ3: 9 | BK3: 1 | BL3: 8 | BM3: 0.67 | BN3: 0 | BO3: 0 | BP3: =ROUND((0.35 * L3) + (0.25 * W3) + (0.15 * U3) + (0.15 * BF3) + (0.1 * AJ3), 1) -> 0.7 | BQ3: 0 | BR3: 0.82 | BS3: =(0.45*L3 + 0.35*M3 + 0.12*AJ3 + 0.08*BF3) * (1 - BR3) -> 0.07884 | BT3: 0 | BU3: 0 | BV3: 73.7 | BW3: 0.085 | BX3: =D3 * ( BP3*0.4 + L3*0.25 + W3*0.15 + AX3*0.1 + BF3*0.1 ) * 100 -> 69.5 | BY3: =E:E*(BQ:BQ*0.35+AT:AT*0.3+AV:AV*0.15+AN:AN*0.1+AO:AO*0.1)*100 -> 0 | BZ3: =ROUND(IF(N(F3)=1, MAX(0, ( (N(BN3)/18)*0.6 + (N(BF3)/10)*0.25 + N(AX3)*0.15 ) * 100 ), 0 ),3) -> 0 | CA3: =ROUND(G:G*(BO:BO*0.45+AZ:AZ*0.3+BB:BB*0.15+BF:BF*0.1)*100,3) -> 0 | CB3: =BX:BX+BY:BY+BZ:BZ + CA:CA -> 69.5 | CC3: =ROUND(0.7 + (BR:BR* 0.2) + (BS:BS * 0.1),3) -> 0.872 | CD3: =ROUND(CB:CB* CC:CC, 2) -> 60.6 | CE3: =ROUND( 1 - ( (D:D * 0.25) + (E:E* 0.2) + (F:F* 0.15) + (G:G* 0.1) ) * AQ:AQ, 3 ) -> 0.875 | CF3: =ROUND( CD:CD* CE:CE, 2 ) -> 53.03 | CG3: =RANK(CF3,CF:CF) -> 23
A4: 253802 | B4: Virat Kohli | C4: Batsman | D4: 1 | E4: 0 | F4: 0 | G4: 0 | H4: 30 | I4: 30 | J4: =ROUND((K4 - MIN($K$2:$K$98)) / (MAX($K$2:$K$98) - MIN($K$2:$K$98)), 1) -> 1 | K4: 1387 | L4: 1 | M4: 0 | N4: Middle | O4: 1 | P4: India | Q4: 0 | R4: 35 | S4: 113 | T4: 55.48 | U4: =ROUND((T4 - MIN(T$2:T$98)) / (MAX(T$2:T$98) - MIN(T$2:T$98)), 1) -> 1 | V4: 146.93 | W4: =ROUND((V4 - MIN(V$2:V$98)) / (MAX(V$2:V$98) - MIN(V$2:V$98)), 1) -> 0.6 | X4: 127 | Y4: 55 | Z4: 3 | AA4: 11 | AB4: 11 | AC4: =IF(AB4>AD4, 3,IF(AB4<AD4, 1, 2)) -> 3 | AD4: 0 | AE4: 0.7 | AF4: 0.0175 | AG4: 9.5 | AH4: 0.05 | AI4: 85 | AJ4: =ROUND((AI4 - MIN(AI$2:AI$98)) / (MAX(AI$2:AI$98) - MIN(AI$2:AI$98)), 1) -> 1 | AK4: 0 | AL4: 0 | AM4: 0 | AN4: 0 | AO4: =ROUND((AP4 - MIN($AP$2:$AP2052)) / (MAX($AP$2:$AP2052) - MIN($AP$2:$AP2052)), 1) -> 0 | AP4: 0 | AQ4: =ROUND((AR4 - MIN($AR$2:$AR2052)) / (MAX($AR$2:$AR2052) - MIN($AR$2:$AR2052)), 1) -> 0.8 | AR4: 7 | AS4: 0 | AT4: 0 | AU4: 0 | AV4: 0 | AW4: 54 | AX4: 0.5 | AY4: 0 | AZ4: =(AP4 - MIN($AP$2:$AP$964)) / (MAX($AP$2:$AP$964) - MIN($AP$2:$AP$964)) -> 0 | BA4: 0 | BB4: 0 | BC4: 0 | BD4: 0 | BE4: 10 | BF4: =ROUND((BE4 - MIN(BE$2:BE$174)) / (MAX(BE$2:BE$174) - MIN(BE$2:BE$174)), 1) -> 1 | BG4: =IF(AND(K4>=800,V4>=145),3,IF(K4>=400,1,2)) -> 3 | BH4: 7 | BI4: =ROUND((BH4 - MIN(BH$2:BH$174)) / (MAX(BH$2:BH$174) - MIN(BH$2:BH$174)), 1) -> 0.3 | BJ4: 9 | BK4: 1 | BL4: 9 | BM4: 1 | BN4: 0 | BO4: 0 | BP4: =ROUND((0.35 * L4) + (0.25 * W4) + (0.15 * U4) + (0.15 * BF4) + (0.1 * AJ4), 1) -> 0.9 | BQ4: 0 | BR4: 0.79 | BS4: =(0.45*L4 + 0.35*M4 + 0.12*AJ4 + 0.08*BF4) * (1 - BR4) -> 0.1365 | BT4: 0 | BU4: 0 | BV4: 62.5 | BW4: 0.073 | BX4: =D4 * ( BP4*0.4 + L4*0.25 + W4*0.15 + AX4*0.1 + BF4*0.1 ) * 100 -> 85 | BY4: =E:E*(BQ:BQ*0.35+AT:AT*0.3+AV:AV*0.15+AN:AN*0.1+AO:AO*0.1)*100 -> 0 | BZ4: =ROUND(IF(N(F4)=1, MAX(0, ( (N(BN4)/18)*0.6 + (N(BF4)/10)*0.25 + N(AX4)*0.15 ) * 100 ), 0 ),3) -> 0 | CA4: =ROUND(G:G*(BO:BO*0.45+AZ:AZ*0.3+BB:BB*0.15+BF:BF*0.1)*100,3) -> 0 | CB4: =BX:BX+BY:BY+BZ:BZ + CA:CA -> 85 | CC4: =ROUND(0.7 + (BR:BR* 0.2) + (BS:BS * 0.1),3) -> 0.872 | CD4: =ROUND(CB:CB* CC:CC, 2) -> 74.12 | CE4: =ROUND( 1 - ( (D:D * 0.25) + (E:E* 0.2) + (F:F* 0.15) + (G:G* 0.1) ) * AQ:AQ, 3 ) -> 0.8 | CF4: =ROUND( CD:CD* CE:CE, 2 ) -> 59.3 | CG4: =RANK(CF4,CF:CF) -> 20
A5: 823703 | B5: Rajat Patidar | C5: Batsman | D5: 1 | E5: 0 | F5: 0 | G5: 0 | H5: 14 | I5: 14 | J5: =ROUND((K5 - MIN($K$2:$K$98)) / (MAX($K$2:$K$98) - MIN($K$2:$K$98)), 1) -> 0.3 | K5: 453 | L5: 0.4 | M5: 0 | N5: Middle | O5: 2 | P5: India | Q5: 0 | R5: 30 | S5: 58 | T5: 32.36 | U5: =ROUND((T5 - MIN(T$2:T$98)) / (MAX(T$2:T$98) - MIN(T$2:T$98)), 1) -> 0.6 | V5: 170.94 | W5: =ROUND((V5 - MIN(V$2:V$98)) / (MAX(V$2:V$98) - MIN(V$2:V$98)), 1) -> 0.7 | X5: 25 | Y5: 36 | Z5: 0 | AA5: 6 | AB5: 11 | AC5: =IF(AB5>AD5, 3,IF(AB5<AD5, 1, 2)) -> 3 | AD5: 2 | AE5: 0.6 | AF5: 0.015 | AG5: 7 | AH5: 0.26 | AI5: 45 | AJ5: =ROUND((AI5 - MIN(AI$2:AI$98)) / (MAX(AI$2:AI$98) - MIN(AI$2:AI$98)), 1) -> 0.5 | AK5: 0 | AL5: 0 | AM5: 0 | AN5: 0 | AO5: =ROUND((AP5 - MIN($AP$2:$AP2053)) / (MAX($AP$2:$AP2053) - MIN($AP$2:$AP2053)), 1) -> 0 | AP5: 0 | AQ5: =ROUND((AR5 - MIN($AR$2:$AR2053)) / (MAX($AR$2:$AR2053) - MIN($AR$2:$AR2053)), 1) -> 0.1 | AR5: 2.5 | AS5: 0 | AT5: 0 | AU5: 0 | AV5: 0 | AW5: 40 | AX5: 0.4 | AY5: 0 | AZ5: =(AP5 - MIN($AP$2:$AP$964)) / (MAX($AP$2:$AP$964) - MIN($AP$2:$AP$964)) -> 0 | BA5: 0 | BB5: 0 | BC5: 0 | BD5: 0 | BE5: 7 | BF5: =ROUND((BE5 - MIN(BE$2:BE$174)) / (MAX(BE$2:BE$174) - MIN(BE$2:BE$174)), 1) -> 0.3 | BG5: =IF(AND(K5>=800,V5>=145),3,IF(K5>=400,1,2)) -> 1 | BH5: 7 | BI5: =ROUND((BH5 - MIN(BH$2:BH$174)) / (MAX(BH$2:BH$174) - MIN(BH$2:BH$174)), 1) -> 0.3 | BJ5: 7 | BK5: 0.71 | BL5: 9 | BM5: 1 | BN5: 0 | BO5: 0 | BP5: =ROUND((0.35 * L5) + (0.25 * W5) + (0.15 * U5) + (0.15 * BF5) + (0.1 * AJ5), 1) -> 0.5 | BQ5: 0 | BR5: 0 | BS5: =(0.45*L5 + 0.35*M5 + 0.12*AJ5 + 0.08*BF5) * (1 - BR5) -> 0.264 | BT5: 0 | BU5: 0 | BV5: 41.95 | BW5: 0.051 | BX5: =D5 * ( BP5*0.4 + L5*0.25 + W5*0.15 + AX5*0.1 + BF5*0.1 ) * 100 -> 47.5 | BY5: =E:E*(BQ:BQ*0.35+AT:AT*0.3+AV:AV*0.15+AN:AN*0.1+AO:AO*0.1)*100 -> 0 | BZ5: =ROUND(IF(N(F5)=1, MAX(0, ( (N(BN5)/18)*0.6 + (N(BF5)/10)*0.25 + N(AX5)*0.15 ) * 100 ), 0 ),3) -> 0 | CA5: =ROUND(G:G*(BO:BO*0.45+AZ:AZ*0.3+BB:BB*0.15+BF:BF*0.1)*100,3) -> 0 | CB5: =BX:BX+BY:BY+BZ:BZ + CA:CA -> 47.5 | CC5: =ROUND(0.7 + (BR:BR* 0.2) + (BS:BS * 0.1),3) -> 0.726 | CD5: =ROUND(CB:CB* CC:CC, 2) -> 34.49 | CE5: =ROUND( 1 - ( (D:D * 0.25) + (E:E* 0.2) + (F:F* 0.15) + (G:G* 0.1) ) * AQ:AQ, 3 ) -> 0.975 | CF5: =ROUND( CD:CD* CE:CE, 2 ) -> 33.63 | CG5: =RANK(CF5,CF:CF) -> 67
A6: 669365 | B6: Phil Salt | C6: Batsman | D6: 1 | E6: 0 | F6: 0 | G6: 1 | H6: 21 | I6: 21 | J6: =ROUND((K6 - MIN($K$2:$K$98)) / (MAX($K$2:$K$98) - MIN($K$2:$K$98)), 1) -> 0.5 | K6: 653 | L6: 0.5 | M6: 0 | N6: Opener | O6: 1 | P6: England | Q6: 1 | R6: 27 | S6: 89 | T6: 34.37 | U6: =ROUND((T6 - MIN(T$2:T$98)) / (MAX(T$2:T$98) - MIN(T$2:T$98)), 1) -> 0.6 | V6: 182 | W6: =ROUND((V6 - MIN(V$2:V$98)) / (MAX(V$2:V$98) - MIN(V$2:V$98)), 1) -> 0.8 | X6: 74 | Y6: 34 | Z6: 0 | AA6: 6 | AB6: 11 | AC6: =IF(AB6>AD6, 3,IF(AB6<AD6, 1, 2)) -> 3 | AD6: 2 | AE6: 0.6 | AF6: 0.015 | AG6: 8 | AH6: 0.243 | AI6: 60 | AJ6: =ROUND((AI6 - MIN(AI$2:AI$98)) / (MAX(AI$2:AI$98) - MIN(AI$2:AI$98)), 1) -> 0.7 | AK6: 0 | AL6: 0 | AM6: 0 | AN6: 0 | AO6: =ROUND((AP6 - MIN($AP$2:$AP2054)) / (MAX($AP$2:$AP2054) - MIN($AP$2:$AP2054)), 1) -> 0 | AP6: 0 | AQ6: =ROUND((AR6 - MIN($AR$2:$AR2054)) / (MAX($AR$2:$AR2054) - MIN($AR$2:$AR2054)), 1) -> 0.2 | AR6: 3 | AS6: 0 | AT6: 0 | AU6: 0 | AV6: 0 | AW6: 39 | AX6: 0.4 | AY6: 12 | AZ6: 0.75 | BA6: 0 | BB6: 0 | BC6: 0 | BD6: 0 | BE6: 8 | BF6: =ROUND((BE6 - MIN(BE$2:BE$174)) / (MAX(BE$2:BE$174) - MIN(BE$2:BE$174)), 1) -> 0.5 | BG6: =IF(AND(K6>=800,V6>=145),3,IF(K6>=400,1,2)) -> 1 | BH6: 7 | BI6: =ROUND((BH6 - MIN(BH$2:BH$174)) / (MAX(BH$2:BH$174) - MIN(BH$2:BH$174)), 1) -> 0.3 | BJ6: 7 | BK6: 0.71 | BL6: 7 | BM6: 0.33 | BN6: 0 | BO6: 0.3 | BP6: =ROUND((0.35 * L6) + (0.25 * W6) + (0.15 * U6) + (0.15 * BF6) + (0.1 * AJ6), 1) -> 0.6 | BQ6: 0 | BR6: 0 | BS6: =(0.45*L6 + 0.35*M6 + 0.12*AJ6 + 0.08*BF6) * (1 - BR6) -> 0.349 | BT6: 0 | BU6: 0 | BV6: 53.55 | BW6: 0.063 | BX6: =D6 * ( BP6*0.4 + L6*0.25 + W6*0.15 + AX6*0.1 + BF6*0.1 ) * 100 -> 57.5 | BY6: =E:E*(BQ:BQ*0.35+AT:AT*0.3+AV:AV*0.15+AN:AN*0.1+AO:AO*0.1)*100 -> 0 | BZ6: =ROUND(IF(N(F6)=1, MAX(0, ( (N(BN6)/18)*0.6 + (N(BF6)/10)*0.25 + N(AX6)*0.15 ) * 100 ), 0 ),3) -> 0 | CA6: =ROUND(G:G*(BO:BO*0.45+AZ:AZ*0.3+BB:BB*0.15+BF:BF*0.1)*100,3) -> 41 | CB6: =BX:BX+BY:BY+BZ:BZ + CA:CA -> 98.5 | CC6: =ROUND(0.7 + (BR:BR* 0.2) + (BS:BS * 0.1),3) -> 0.735 | CD6: =ROUND(CB:CB* CC:CC, 2) -> 72.4 | CE6: =ROUND( 1 - ( (D:D * 0.25) + (E:E* 0.2) + (F:F* 0.15) + (G:G* 0.1) ) * AQ:AQ, 3 ) -> 0.93 | CF6: =ROUND( CD:CD* CE:CE, 2 ) -> 67.33 | CG6: =RANK(CF6,CF:CF) -> 16
A7: 604553 | B7: Nicholas Pooran | C7: Batsman | D7: 1 | E7: 0 | F7: 0 | G7: 0 | H7: 29 | I7: 20 | J7: =ROUND((K7 - MIN($K$2:$K$98)) / (MAX($K$2:$K$98) - MIN($K$2:$K$98)), 1) -> 0.6 | K7: 857 | L7: 0.4 | M7: 0 | N7: Finisher | O7: 3 | P7: West Indies | Q7: 1 | R7: 28 | S7: 75 | T7: 42.85 | U7: =ROUND((T7 - MIN(T$2:T$98)) / (MAX(T$2:T$98) - MIN(T$2:T$98)), 1) -> 0.8 | V7: 175.98 | W7: =ROUND((V7 - MIN(V$2:V$98)) / (MAX(V$2:V$98) - MIN(V$2:V$98)), 1) -> 0.7 | X7: 61 | Y7: 62 | Z7: 0 | AA7: 5 | AB7: 8.75 | AC7: =IF(AB7>AD7, 3,IF(AB7<AD7, 1, 2)) -> 3 | AD7: 2 | AE7: 0.6 | AF7: 0.015 | AG7: 8 | AH7: 0.5 | AI7: 65 | AJ7: =ROUND((AI7 - MIN(AI$2:AI$98)) / (MAX(AI$2:AI$98) - MIN(AI$2:AI$98)), 1) -> 0.8 | AK7: 0 | AL7: 0 | AM7: 0 | AN7: 0 | AO7: =ROUND((AP7 - MIN($AP$2:$AP2055)) / (MAX($AP$2:$AP2055) - MIN($AP$2:$AP2055)), 1) -> 0 | AP7: 0 | AQ7: =ROUND((AR7 - MIN($AR$2:$AR2055)) / (MAX($AR$2:$AR2055) - MIN($AR$2:$AR2055)), 1) -> 0.3 | AR7: 3.5 | AS7: 0 | AT7: 0 | AU7: 0 | AV7: 0 | AW7: 62 | AX7: 0.6 | AY7: 0 | AZ7: =(AP7 - MIN($AP$2:$AP$964)) / (MAX($AP$2:$AP$964) - MIN($AP$2:$AP$964)) -> 0 | BA7: 0 | BB7: 0 | BC7: 0 | BD7: 0 | BE7: 8 | BF7: =ROUND((BE7 - MIN(BE$2:BE$174)) / (MAX(BE$2:BE$174) - MIN(BE$2:BE$174)), 1) -> 0.5 | BG7: =IF(AND(K7>=800,V7>=145),3,IF(K7>=400,1,2)) -> 3 | BH7: 8 | BI7: =ROUND((BH7 - MIN(BH$2:BH$174)) / (MAX(BH$2:BH$174) - MIN(BH$2:BH$174)), 1) -> 0.7 | BJ7: 8 | BK7: 0.86 | BL7: 8 | BM7: 0.67 | BN7: 0 | BO7: 0 | BP7: =ROUND((0.35 * L7) + (0.25 * W7) + (0.15 * U7) + (0.15 * BF7) + (0.1 * AJ7), 1) -> 0.6 | BQ7: 0 | BR7: 0.79 | BS7: =(0.45*L7 + 0.35*M7 + 0.12*AJ7 + 0.08*BF7) * (1 - BR7) -> 0.06636 | BT7: 0 | BU7: 0 | BV7: 62.3 | BW7: 0.073 | BX7: =D7 * ( BP7*0.4 + L7*0.25 + W7*0.15 + AX7*0.1 + BF7*0.1 ) * 100 -> 55.5 | BY7: =E:E*(BQ:BQ*0.35+AT:AT*0.3+AV:AV*0.15+AN:AN*0.1+AO:AO*0.1)*100 -> 0 | BZ7: =ROUND(IF(N(F7)=1, MAX(0, ( (N(BN7)/18)*0.6 + (N(BF7)/10)*0.25 + N(AX7)*0.15 ) * 100 ), 0 ),3) -> 0 | CA7: =ROUND(G:G*(BO:BO*0.45+AZ:AZ*0.3+BB:BB*0.15+BF:BF*0.1)*100,3) -> 0 | CB7: =BX:BX+BY:BY+BZ:BZ + CA:CA -> 55.5 | CC7: =ROUND(0.7 + (BR:BR* 0.2) + (BS:BS * 0.1),3) -> 0.865 | CD7: =ROUND(CB:CB* CC:CC, 2) -> 48.01 | CE7: =ROUND( 1 - ( (D:D * 0.25) + (E:E* 0.2) + (F:F* 0.15) + (G:G* 0.1) ) * AQ:AQ, 3 ) -> 0.925 | CF7: =ROUND( CD:CD* CE:CE, 2 ) -> 44.41 | CG7: =RANK(CF7,CF:CF) -> 41
A8: 1060380 | B8: Ruturaj Gaikwad | C8: Batsman | D8: 1 | E8: 0 | F8: 0 | G8: 0 | H8: 29 | I8: 29 | J8: =ROUND((K8 - MIN($K$2:$K$98)) / (MAX($K$2:$K$98) - MIN($K$2:$K$98)), 1) -> 0.8 | K8: 1173 | L8: 0.6 | M8: 0 | N8: Opener | O8: 1 | P8: India | Q8: 0 | R8: 27 | S8: 108 | T8: 46.92 | U8: =ROUND((T8 - MIN(T$2:T$98)) / (MAX(T$2:T$98) - MIN(T$2:T$98)), 1) -> 0.8 | V8: 144.28 | W8: =ROUND((V8 - MIN(V$2:V$98)) / (MAX(V$2:V$98) - MIN(V$2:V$98)), 1) -> 0.6 | X8: 104 | Y8: 48 | Z8: 1 | AA8: 8 | AB8: 27 | AC8: =IF(AB8>AD8, 3,IF(AB8<AD8, 1, 2)) -> 3 | AD8: 0 | AE8: 0.7 | AF8: 0.0175 | AG8: 7.5 | AH8: 0.01 | AI8: 75 | AJ8: =ROUND((AI8 - MIN(AI$2:AI$98)) / (MAX(AI$2:AI$98) - MIN(AI$2:AI$98)), 1) -> 0.9 | AK8: 0 | AL8: 0 | AM8: 0 | AN8: 0 | AO8: =ROUND((AP8 - MIN($AP$2:$AP2056)) / (MAX($AP$2:$AP2056) - MIN($AP$2:$AP2056)), 1) -> 0 | AP8: 0 | AQ8: =ROUND((AR8 - MIN($AR$2:$AR2056)) / (MAX($AR$2:$AR2056) - MIN($AR$2:$AR2056)), 1) -> 0.3 | AR8: 4 | AS8: 0 | AT8: 0 | AU8: 0 | AV8: 0 | AW8: 53 | AX8: 0.5 | AY8: 0 | AZ8: =(AP8 - MIN($AP$2:$AP$964)) / (MAX($AP$2:$AP$964) - MIN($AP$2:$AP$964)) -> 0 | BA8: 0 | BB8: 0 | BC8: 0 | BD8: 0 | BE8: 7.5 | BF8: =ROUND((BE8 - MIN(BE$2:BE$174)) / (MAX(BE$2:BE$174) - MIN(BE$2:BE$174)), 1) -> 0.4 | BG8: =IF(AND(K8>=800,V8>=145),3,IF(K8>=400,1,2)) -> 1 | BH8: 8 | BI8: =ROUND((BH8 - MIN(BH$2:BH$174)) / (MAX(BH$2:BH$174) - MIN(BH$2:BH$174)), 1) -> 0.7 | BJ8: 8 | BK8: 0.86 | BL8: 8 | BM8: 0.67 | BN8: 0 | BO8: 0 | BP8: =ROUND((0.35 * L8) + (0.25 * W8) + (0.15 * U8) + (0.15 * BF8) + (0.1 * AJ8), 1) -> 0.6 | BQ8: 0 | BR8: 0.76 | BS8: =(0.45*L8 + 0.35*M8 + 0.12*AJ8 + 0.08*BF8) * (1 - BR8) -> 0.0984 | BT8: 0 | BU8: 0 | BV8: 60 | BW8: 0.07 | BX8: =D8 * ( BP8*0.4 + L8*0.25 + W8*0.15 + AX8*0.1 + BF8*0.1 ) * 100 -> 57 | BY8: =E:E*(BQ:BQ*0.35+AT:AT*0.3+AV:AV*0.15+AN:AN*0.1+AO:AO*0.1)*100 -> 0 | BZ8: =ROUND(IF(N(F8)=1, MAX(0, ( (N(BN8)/18)*0.6 + (N(BF8)/10)*0.25 + N(AX8)*0.15 ) * 100 ), 0 ),3) -> 0 | CA8: =ROUND(G:G*(BO:BO*0.45+AZ:AZ*0.3+BB:BB*0.15+BF:BF*0.1)*100,3) -> 0 | CB8: =BX:BX+BY:BY+BZ:BZ + CA:CA -> 57 | CC8: =ROUND(0.7 + (BR:BR* 0.2) + (BS:BS * 0.1),3) -> 0.862 | CD8: =ROUND(CB:CB* CC:CC, 2) -> 49.13 | CE8: =ROUND( 1 - ( (D:D * 0.25) + (E:E* 0.2) + (F:F* 0.15) + (G:G* 0.1) ) * AQ:AQ, 3 ) -> 0.925 | CF8: =ROUND( CD:CD* CE:CE, 2 ) -> 45.45 | CG8: =RANK(CF8,CF:CF) -> 38
A9: 1159186 | B9: Yashasvi Jaiswal | C9: Batsman | D9: 1 | E9: 0 | F9: 0 | G9: 0 | H9: 31 | I9: 31 | J9: =ROUND((K9 - MIN($K$2:$K$98)) / (MAX($K$2:$K$98) - MIN($K$2:$K$98)), 1) -> 0.8 | K9: 1103 | L9: 0.4 | M9: 0 | N9: Opener | O9: 1 | P9: India | Q9: 0 | R9: 22 | S9: 124 | T9: 38.03 | U9: =ROUND((T9 - MIN(T$2:T$98)) / (MAX(T$2:T$98) - MIN(T$2:T$98)), 1) -> 0.7 | V9: 159.86 | W9: =ROUND((V9 - MIN(V$2:V$98)) / (MAX(V$2:V$98) - MIN(V$2:V$98)), 1) -> 0.7 | X9: 138 | Y9: 46 | Z9: 2 | AA9: 6 | AB9: 26.75 | AC9: =IF(AB9>AD9, 3,IF(AB9<AD9, 1, 2)) -> 3 | AD9: 0 | AE9: 0.6 | AF9: 0.015 | AG9: 7.5 | AH9: 0.5 | AI9: 65 | AJ9: =ROUND((AI9 - MIN(AI$2:AI$98)) / (MAX(AI$2:AI$98) - MIN(AI$2:AI$98)), 1) -> 0.8 | AK9: 0 | AL9: 0 | AM9: 0 | AN9: 0 | AO9: =ROUND((AP9 - MIN($AP$2:$AP2057)) / (MAX($AP$2:$AP2057) - MIN($AP$2:$AP2057)), 1) -> 0 | AP9: 0 | AQ9: =ROUND((AR9 - MIN($AR$2:$AR2057)) / (MAX($AR$2:$AR2057) - MIN($AR$2:$AR2057)), 1) -> 0 | AR9: 2 | AS9: 0 | AT9: 0 | AU9: 0 | AV9: 0 | AW9: 31 | AX9: 0.3 | AY9: 0 | AZ9: =(AP9 - MIN($AP$2:$AP$964)) / (MAX($AP$2:$AP$964) - MIN($AP$2:$AP$964)) -> 0 | BA9: 0 | BB9: 0 | BC9: 0 | BD9: 0 | BE9: 7 | BF9: =ROUND((BE9 - MIN(BE$2:BE$174)) / (MAX(BE$2:BE$174) - MIN(BE$2:BE$174)), 1) -> 0.3 | BG9: =IF(AND(K9>=800,V9>=145),3,IF(K9>=400,1,2)) -> 3 | BH9: 8 | BI9: =ROUND((BH9 - MIN(BH$2:BH$174)) / (MAX(BH$2:BH$174) - MIN(BH$2:BH$174)), 1) -> 0.7 | BJ9: 9 | BK9: 1 | BL9: 7 | BM9: 0.33 | BN9: 0 | BO9: 0 | BP9: =ROUND((0.35 * L9) + (0.25 * W9) + (0.15 * U9) + (0.15 * BF9) + (0.1 * AJ9), 1) -> 0.5 | BQ9: 0 | BR9: 0.75 | BS9: =(0.45*L9 + 0.35*M9 + 0.12*AJ9 + 0.08*BF9) * (1 - BR9) -> 0.075 | BT9: 0 | BU9: 0 | BV9: 67.9 | BW9: 0.079 | BX9: =D9 * ( BP9*0.4 + L9*0.25 + W9*0.15 + AX9*0.1 + BF9*0.1 ) * 100 -> 46.5 | BY9: =E:E*(BQ:BQ*0.35+AT:AT*0.3+AV:AV*0.15+AN:AN*0.1+AO:AO*0.1)*100 -> 0 | BZ9: =ROUND(IF(N(F9)=1, MAX(0, ( (N(BN9)/18)*0.6 + (N(BF9)/10)*0.25 + N(AX9)*0.15 ) * 100 ), 0 ),3) -> 0 | CA9: =ROUND(G:G*(BO:BO*0.45+AZ:AZ*0.3+BB:BB*0.15+BF:BF*0.1)*100,3) -> 0 | CB9: =BX:BX+BY:BY+BZ:BZ + CA:CA -> 46.5 | CC9: =ROUND(0.7 + (BR:BR* 0.2) + (BS:BS * 0.1),3) -> 0.858 | CD9: =ROUND(CB:CB* CC:CC, 2) -> 39.9 | CE9: =ROUND( 1 - ( (D:D * 0.25) + (E:E* 0.2) + (F:F* 0.15) + (G:G* 0.1) ) * AQ:AQ, 3 ) -> 1 | CF9: =ROUND( CD:CD* CE:CE, 2 ) -> 39.9 | CG9: =RANK(CF9,CF:CF) -> 47
A10: 44828 | B10: Faf du Plessis | C10: Batsman | D10: 1 | E10: 0 | F10: 0 | G10: 0 | H10: 30 | I10: 30 | J10: =ROUND((K10 - MIN($K$2:$K$98)) / (MAX($K$2:$K$98) - MIN($K$2:$K$98)), 1) -> 0.9 | K10: 1193 | L10: 0.6 | M10: 0 | N10: Opener | O10: 1 | P10: South Africa | Q10: 1 | R10: 40 | S10: 84 | T10: 41.14 | U10: =ROUND((T10 - MIN(T$2:T$98)) / (MAX(T$2:T$98) - MIN(T$2:T$98)), 1) -> 0.7 | V10: 154.33 | W10: =ROUND((V10 - MIN(V$2:V$98)) / (MAX(V$2:V$98) - MIN(V$2:V$98)), 1) -> 0.6 | X10: 110 | Y10: 57 | Z10: 0 | AA10: 12 | AB10: 23.75 | AC10: =IF(AB10>AD10, 3,IF(AB10<AD10, 1, 2)) -> 3 | AD10: 2 | AE10: 0.7 | AF10: 0.0175 | AG10: 6.5 | AH10: 0.074 | AI10: 80 | AJ10: =ROUND((AI10 - MIN(AI$2:AI$98)) / (MAX(AI$2:AI$98) - MIN(AI$2:AI$98)), 1) -> 0.9 | AK10: 0 | AL10: 0 | AM10: 0 | AN10: 0 | AO10: =ROUND((AP10 - MIN($AP$2:$AP2058)) / (MAX($AP$2:$AP2058) - MIN($AP$2:$AP2058)), 1) -> 0 | AP10: 0 | AQ10: =ROUND((AR10 - MIN($AR$2:$AR2058)) / (MAX($AR$2:$AR2058) - MIN($AR$2:$AR2058)), 1) -> 0.8 | AR10: 6.5 | AS10: 0 | AT10: 0 | AU10: 0 | AV10: 0 | AW10: 29 | AX10: 0.3 | AY10: 0 | AZ10: =(AP10 - MIN($AP$2:$AP$964)) / (MAX($AP$2:$AP$964) - MIN($AP$2:$AP$964)) -> 0 | BA10: 0 | BB10: 0 | BC10: 0 | BD10: 0 | BE10: 6.5 | BF10: =ROUND((BE10 - MIN(BE$2:BE$174)) / (MAX(BE$2:BE$174) - MIN(BE$2:BE$174)), 1) -> 0.1 | BG10: =IF(AND(K10>=800,V10>=145),3,IF(K10>=400,1,2)) -> 3 | BH10: 7 | BI10: =ROUND((BH10 - MIN(BH$2:BH$174)) / (MAX(BH$2:BH$174) - MIN(BH$2:BH$174)), 1) -> 0.3 | BJ10: 8 | BK10: 0.86 | BL10: 7 | BM10: 0.33 | BN10: 0 | BO10: 0 | BP10: =ROUND((0.35 * L10) + (0.25 * W10) + (0.15 * U10) + (0.15 * BF10) + (0.1 * AJ10), 1) -> 0.6 | BQ10: 0 | BR10: 0.58 | BS10: =(0.45*L10 + 0.35*M10 + 0.12*AJ10 + 0.08*BF10) * (1 - BR10) -> 0.16212 | BT10: 0 | BU10: 0 | BV10: 55.6 | BW10: 0.066 | BX10: =D10 * ( BP10*0.4 + L10*0.25 + W10*0.15 + AX10*0.1 + BF10*0.1 ) * 100 -> 52 | BY10: =E:E*(BQ:BQ*0.35+AT:AT*0.3+AV:AV*0.15+AN:AN*0.1+AO:AO*0.1)*100 -> 0 | BZ10: =ROUND(IF(N(F10)=1, MAX(0, ( (N(BN10)/18)*0.6 + (N(BF10)/10)*0.25 + N(AX10)*0.15 ) * 100 ), 0 ),3) -> 0 | CA10: =ROUND(G:G*(BO:BO*0.45+AZ:AZ*0.3+BB:BB*0.15+BF:BF*0.1)*100,3) -> 0 | CB10: =BX:BX+BY:BY+BZ:BZ + CA:CA -> 52 | CC10: =ROUND(0.7 + (BR:BR* 0.2) + (BS:BS * 0.1),3) -> 0.832 | CD10: =ROUND(CB:CB* CC:CC, 2) -> 43.26 | CE10: =ROUND( 1 - ( (D:D * 0.25) + (E:E* 0.2) + (F:F* 0.15) + (G:G* 0.1) ) * AQ:AQ, 3 ) -> 0.8 | CF10: =ROUND( CD:CD* CE:CE, 2 ) -> 34.61 | CG10: =RANK(CF10,CF:CF) -> 61
A11: 530011 | B11: Travis Head | C11: Batsman | D11: 1 | E11: 0 | F11: 0 | G11: 0 | H11: 15 | I11: 15 | J11: =ROUND((K11 - MIN($K$2:$K$98)) / (MAX($K$2:$K$98) - MIN($K$2:$K$98)), 1) -> 0.4 | K11: 567 | L11: 0.5 | M11: 0 | N11: Middle | O11: 1 | P11: Australia | Q11: 1 | R11: 30 | S11: 102 | T11: 40.5 | U11: =ROUND((T11 - MIN(T$2:T$98)) / (MAX(T$2:T$98) - MIN(T$2:T$98)), 1) -> 0.7 | V11: 191.55 | W11: =ROUND((V11 - MIN(V$2:V$98)) / (MAX(V$2:V$98) - MIN(V$2:V$98)), 1) -> 0.8 | X11: 64 | Y11: 32 | Z11: 1 | AA11: 4 | AB11: 18 | AC11: =IF(AB11>AD11, 3,IF(AB11<AD11, 1, 2)) -> 3 | AD11: 2 | AE11: 0.6 | AF11: 0.015 | AG11: 8.5 | AH11: 0.25 | AI11: 70 | AJ11: =ROUND((AI11 - MIN(AI$2:AI$98)) / (MAX(AI$2:AI$98) - MIN(AI$2:AI$98)), 1) -> 0.8 | AK11: 0 | AL11: 0 | AM11: 0 | AN11: 0 | AO11: =ROUND((AP11 - MIN($AP$2:$AP2059)) / (MAX($AP$2:$AP2059) - MIN($AP$2:$AP2059)), 1) -> 0 | AP11: 0 | AQ11: =ROUND((AR11 - MIN($AR$2:$AR2059)) / (MAX($AR$2:$AR2059) - MIN($AR$2:$AR2059)), 1) -> 0.4 | AR11: 4.5 | AS11: 0 | AT11: 0 | AU11: 0 | AV11: 0 | AW11: 40 | AX11: 0.4 | AY11: 0 | AZ11: =(AP11 - MIN($AP$2:$AP$964)) / (MAX($AP$2:$AP$964) - MIN($AP$2:$AP$964)) -> 0 | BA11: 0 | BB11: 0 | BC11: 0 | BD11: 0 | BE11: 8.5 | BF11: =ROUND((BE11 - MIN(BE$2:BE$174)) / (MAX(BE$2:BE$174) - MIN(BE$2:BE$174)), 1) -> 0.6 | BG11: =IF(AND(K11>=800,V11>=145),3,IF(K11>=400,1,2)) -> 1 | BH11: 7 | BI11: =ROUND((BH11 - MIN(BH$2:BH$174)) / (MAX(BH$2:BH$174) - MIN(BH$2:BH$174)), 1) -> 0.3 | BJ11: 7 | BK11: 0.71 | BL11: 6 | BM11: 0 | BN11: 0 | BO11: 0 | BP11: =ROUND((0.35 * L11) + (0.25 * W11) + (0.15 * U11) + (0.15 * BF11) + (0.1 * AJ11), 1) -> 0.7 | BQ11: 0 | BR11: 0.83 | BS11: =(0.45*L11 + 0.35*M11 + 0.12*AJ11 + 0.08*BF11) * (1 - BR11) -> 0.06273 | BT11: 0 | BU11: 0 | BV11: 59.35 | BW11: 0.07 | BX11: =D11 * ( BP11*0.4 + L11*0.25 + W11*0.15 + AX11*0.1 + BF11*0.1 ) * 100 -> 62.5 | BY11: =E:E*(BQ:BQ*0.35+AT:AT*0.3+AV:AV*0.15+AN:AN*0.1+AO:AO*0.1)*100 -> 0 | BZ11: =ROUND(IF(N(F11)=1, MAX(0, ( (N(BN11)/18)*0.6 + (N(BF11)/10)*0.25 + N(AX11)*0.15 ) * 100 ), 0 ),3) -> 0 | CA11: =ROUND(G:G*(BO:BO*0.45+AZ:AZ*0.3+BB:BB*0.15+BF:BF*0.1)*100,3) -> 0 | CB11: =BX:BX+BY:BY+BZ:BZ + CA:CA -> 62.5 | CC11: =ROUND(0.7 + (BR:BR* 0.2) + (BS:BS * 0.1),3) -> 0.872 | CD11: =ROUND(CB:CB* CC:CC, 2) -> 54.5 | CE11: =ROUND( 1 - ( (D:D * 0.25) + (E:E* 0.2) + (F:F* 0.15) + (G:G* 0.1) ) * AQ:AQ, 3 ) -> 0.9 | CF11: =ROUND( CD:CD* CE:CE, 2 ) -> 49.05 | CG11: =RANK(CF11,CF:CF) -> 28
A12: 436757 | B12: Heinrich Klaasen | C12: Batsman | D12: 1 | E12: 0 | F12: 0 | G12: 1 | H12: 26 | I12: 26 | J12: =ROUND((K12 - MIN($K$2:$K$98)) / (MAX($K$2:$K$98) - MIN($K$2:$K$98)), 1) -> 0.7 | K12: 927 | L12: 0.5 | M12: 0 | N12: Middle | O12: 3 | P12: South Africa | Q12: 1 | R12: 32 | S12: 104 | T12: 44.14 | U12: =ROUND((T12 - MIN(T$2:T$98)) / (MAX(T$2:T$98) - MIN(T$2:T$98)), 1) -> 0.8 | V12: 173.92 | W12: =ROUND((V12 - MIN(V$2:V$98)) / (MAX(V$2:V$98) - MIN(V$2:V$98)), 1) -> 0.7 | X12: 51 | Y12: 63 | Z12: 1 | AA12: 6 | AB12: 18 | AC12: =IF(AB12>AD12, 3,IF(AB12<AD12, 1, 2)) -> 3 | AD12: 2 | AE12: 0.6 | AF12: 0.015 | AG12: 9 | AH12: 0.125 | AI12: 50 | AJ12: =ROUND((AI12 - MIN(AI$2:AI$98)) / (MAX(AI$2:AI$98) - MIN(AI$2:AI$98)), 1) -> 0.6 | AK12: 2 | AL12: 0 | AM12: 0 | AN12: 0 | AO12: =ROUND((AP12 - MIN($AP$2:$AP2060)) / (MAX($AP$2:$AP2060) - MIN($AP$2:$AP2060)), 1) -> 0 | AP12: 0 | AQ12: =ROUND((AR12 - MIN($AR$2:$AR2060)) / (MAX($AR$2:$AR2060) - MIN($AR$2:$AR2060)), 1) -> 0.5 | AR12: 5 | AS12: 0 | AT12: 0 | AU12: 0 | AV12: 0 | AW12: 39 | AX12: 0.4 | AY12: 10 | AZ12: 0.67 | BA12: 20 | BB12: 0.444 | BC12: 0 | BD12: 0 | BE12: 9 | BF12: =ROUND((BE12 - MIN(BE$2:BE$174)) / (MAX(BE$2:BE$174) - MIN(BE$2:BE$174)), 1) -> 0.8 | BG12: =IF(AND(K12>=800,V12>=145),3,IF(K12>=400,1,2)) -> 3 | BH12: 6 | BI12: =ROUND((BH12 - MIN(BH$2:BH$174)) / (MAX(BH$2:BH$174) - MIN(BH$2:BH$174)), 1) -> 0 | BJ12: 9 | BK12: 1 | BL12: 8 | BM12: 0.67 | BN12: 0 | BO12: 0.4 | BP12: =ROUND((0.35 * L12) + (0.25 * W12) + (0.15 * U12) + (0.15 * BF12) + (0.1 * AJ12), 1) -> 0.7 | BQ12: 0 | BR12: 0.8 | BS12: =(0.45*L12 + 0.35*M12 + 0.12*AJ12 + 0.08*BF12) * (1 - BR12) -> 0.0722 | BT12: 0 | BU12: 0 | BV12: 60.4 | BW12: 0.071 | BX12: =D12 * ( BP12*0.4 + L12*0.25 + W12*0.15 + AX12*0.1 + BF12*0.1 ) * 100 -> 63 | BY12: =E:E*(BQ:BQ*0.35+AT:AT*0.3+AV:AV*0.15+AN:AN*0.1+AO:AO*0.1)*100 -> 0 | BZ12: =ROUND(IF(N(F12)=1, MAX(0, ( (N(BN12)/18)*0.6 + (N(BF12)/10)*0.25 + N(AX12)*0.15 ) * 100 ), 0 ),3) -> 0 | CA12: =ROUND(G:G*(BO:BO*0.45+AZ:AZ*0.3+BB:BB*0.15+BF:BF*0.1)*100,3) -> 52.76 | CB12: =BX:BX+BY:BY+BZ:BZ + CA:CA -> 115.76 | CC12: =ROUND(0.7 + (BR:BR* 0.2) + (BS:BS * 0.1),3) -> 0.867 | CD12: =ROUND(CB:CB* CC:CC, 2) -> 100.36 | CE12: =ROUND( 1 - ( (D:D * 0.25) + (E:E* 0.2) + (F:F* 0.15) + (G:G* 0.1) ) * AQ:AQ, 3 ) -> 0.825 | CF12: =ROUND( CD:CD* CE:CE, 2 ) -> 82.8 | CG12: =RANK(CF12,CF:CF) -> 12
A13: 1079434 | B13: Riyan Parag | C13: Batsman | D13: 1 | E13: 0 | F13: 0 | G13: 0 | H13: 22 | I13: 22 | J13: =ROUND((K13 - MIN($K$2:$K$98)) / (MAX($K$2:$K$98) - MIN($K$2:$K$98)), 1) -> 0.5 | K13: 666 | L13: 0.4 | M13: 0 | N13: Middle | O13: 2 | P13: India | Q13: 0 | R13: 22 | S13: 84 | T13: 37 | U13: =ROUND((T13 - MIN(T$2:T$98)) / (MAX(T$2:T$98) - MIN(T$2:T$98)), 1) -> 0.7 | V13: 143.23 | W13: =ROUND((V13 - MIN(V$2:V$98)) / (MAX(V$2:V$98) - MIN(V$2:V$98)), 1) -> 0.6 | X13: 45 | Y13: 38 | Z13: 0 | AA13: 4 | AB13: 15.75 | AC13: =IF(AB13>AD13, 3,IF(AB13<AD13, 1, 2)) -> 3 | AD13: 0 | AE13: 0.5 | AF13: 0.0125 | AG13: 8.5 | AH13: 0.05 | AI13: 40 | AJ13: =ROUND((AI13 - MIN(AI$2:AI$98)) / (MAX(AI$2:AI$98) - MIN(AI$2:AI$98)), 1) -> 0.4 | AK13: 0 | AL13: 0 | AM13: 0 | AN13: 0 | AO13: =ROUND((AP13 - MIN($AP$2:$AP2061)) / (MAX($AP$2:$AP2061) - MIN($AP$2:$AP2061)), 1) -> 0 | AP13: 0 | AQ13: =ROUND((AR13 - MIN($AR$2:$AR2061)) / (MAX($AR$2:$AR2061) - MIN($AR$2:$AR2061)), 1) -> 0.1 | AR13: 2.5 | AS13: 0 | AT13: 0 | AU13: 0 | AV13: 0 | AW13: 52 | AX13: 0.5 | AY13: 0 | AZ13: =(AP13 - MIN($AP$2:$AP$964)) / (MAX($AP$2:$AP$964) - MIN($AP$2:$AP$964)) -> 0 | BA13: 0 | BB13: 0 | BC13: 0 | BD13: 0 | BE13: 8.5 | BF13: =ROUND((BE13 - MIN(BE$2:BE$174)) / (MAX(BE$2:BE$174) - MIN(BE$2:BE$174)), 1) -> 0.6 | BG13: =IF(AND(K13>=800,V13>=145),3,IF(K13>=400,1,2)) -> 1 | BH13: 6 | BI13: =ROUND((BH13 - MIN(BH$2:BH$174)) / (MAX(BH$2:BH$174) - MIN(BH$2:BH$174)), 1) -> 0 | BJ13: 6 | BK13: 0.57 | BL13: 9 | BM13: 1 | BN13: 0 | BO13: 0 | BP13: =ROUND((0.35 * L13) + (0.25 * W13) + (0.15 * U13) + (0.15 * BF13) + (0.1 * AJ13), 1) -> 0.5 | BQ13: 0 | BR13: 0.63 | BS13: =(0.45*L13 + 0.35*M13 + 0.12*AJ13 + 0.08*BF13) * (1 - BR13) -> 0.10212 | BT13: 0 | BU13: 0 | BV13: 35.15 | BW13: 0.043 | BX13: =D13 * ( BP13*0.4 + L13*0.25 + W13*0.15 + AX13*0.1 + BF13*0.1 ) * 100 -> 50 | BY13: =E:E*(BQ:BQ*0.35+AT:AT*0.3+AV:AV*0.15+AN:AN*0.1+AO:AO*0.1)*100 -> 0 | BZ13: =ROUND(IF(N(F13)=1, MAX(0, ( (N(BN13)/18)*0.6 + (N(BF13)/10)*0.25 + N(AX13)*0.15 ) * 100 ), 0 ),3) -> 0 | CA13: =ROUND(G:G*(BO:BO*0.45+AZ:AZ*0.3+BB:BB*0.15+BF:BF*0.1)*100,3) -> 0 | CB13: =BX:BX+BY:BY+BZ:BZ + CA:CA -> 50 | CC13: =ROUND(0.7 + (BR:BR* 0.2) + (BS:BS * 0.1),3) -> 0.836 | CD13: =ROUND(CB:CB* CC:CC, 2) -> 41.8 | CE13: =ROUND( 1 - ( (D:D * 0.25) + (E:E* 0.2) + (F:F* 0.15) + (G:G* 0.1) ) * AQ:AQ, 3 ) -> 0.975 | CF13: =ROUND( CD:CD* CE:CE, 2 ) -> 40.76 | CG13: =RANK(CF13,CF:CF) -> 46
A14: 931581 | B14: Rishab Pant | C14: Batsman | D14: 1 | E14: 0 | F14: 0 | G14: 0 | H14: 13 | I14: 13 | J14: =ROUND((K14 - MIN($K$2:$K$98)) / (MAX($K$2:$K$98) - MIN($K$2:$K$98)), 1) -> 0.3 | K14: 446 | L14: 0.4 | M14: 0 | N14: Finisher | O14: 2 | P14: India | Q14: 0 | R14: 26 | S14: 88 | T14: 40.55 | U14: =ROUND((T14 - MIN(T$2:T$98)) / (MAX(T$2:T$98) - MIN(T$2:T$98)), 1) -> 0.7 | V14: 155.4 | W14: =ROUND((V14 - MIN(V$2:V$98)) / (MAX(V$2:V$98) - MIN(V$2:V$98)), 1) -> 0.6 | X14: 36 | Y14: 25 | Z14: 0 | AA14: 3 | AB14: 14 | AC14: =IF(AB14>AD14, 3,IF(AB14<AD14, 1, 2)) -> 3 | AD14: 2 | AE14: 0.7 | AF14: 0.0175 | AG14: 8 | AH14: 0.054 | AI14: 60 | AJ14: =ROUND((AI14 - MIN(AI$2:AI$98)) / (MAX(AI$2:AI$98) - MIN(AI$2:AI$98)), 1) -> 0.7 | AK14: 0 | AL14: 0 | AM14: 0 | AN14: 0 | AO14: =ROUND((AP14 - MIN($AP$2:$AP2062)) / (MAX($AP$2:$AP2062) - MIN($AP$2:$AP2062)), 1) -> 0 | AP14: 0 | AQ14: =ROUND((AR14 - MIN($AR$2:$AR2062)) / (MAX($AR$2:$AR2062) - MIN($AR$2:$AR2062)), 1) -> 0.3 | AR14: 3.5 | AS14: 0 | AT14: 0 | AU14: 0 | AV14: 0 | AW14: 40 | AX14: 0.4 | AY14: 0 | AZ14: =(AP14 - MIN($AP$2:$AP$964)) / (MAX($AP$2:$AP$964) - MIN($AP$2:$AP$964)) -> 0 | BA14: 0 | BB14: 0 | BC14: 0 | BD14: 0 | BE14: 8 | BF14: =ROUND((BE14 - MIN(BE$2:BE$174)) / (MAX(BE$2:BE$174) - MIN(BE$2:BE$174)), 1) -> 0.5 | BG14: =IF(AND(K14>=800,V14>=145),3,IF(K14>=400,1,2)) -> 1 | BH14: 7 | BI14: =ROUND((BH14 - MIN(BH$2:BH$174)) / (MAX(BH$2:BH$174) - MIN(BH$2:BH$174)), 1) -> 0.3 | BJ14: 8 | BK14: 0.86 | BL14: 8 | BM14: 0.67 | BN14: 0 | BO14: 0 | BP14: =ROUND((0.35 * L14) + (0.25 * W14) + (0.15 * U14) + (0.15 * BF14) + (0.1 * AJ14), 1) -> 0.5 | BQ14: 0 | BR14: 0.74 | BS14: =(0.45*L14 + 0.35*M14 + 0.12*AJ14 + 0.08*BF14) * (1 - BR14) -> 0.07904 | BT14: 0 | BU14: 0 | BV14: 55.3 | BW14: 0.065 | BX14: =D14 * ( BP14*0.4 + L14*0.25 + W14*0.15 + AX14*0.1 + BF14*0.1 ) * 100 -> 48 | BY14: =E:E*(BQ:BQ*0.35+AT:AT*0.3+AV:AV*0.15+AN:AN*0.1+AO:AO*0.1)*100 -> 0 | BZ14: =ROUND(IF(N(F14)=1, MAX(0, ( (N(BN14)/18)*0.6 + (N(BF14)/10)*0.25 + N(AX14)*0.15 ) * 100 ), 0 ),3) -> 0 | CA14: =ROUND(G:G*(BO:BO*0.45+AZ:AZ*0.3+BB:BB*0.15+BF:BF*0.1)*100,3) -> 0 | CB14: =BX:BX+BY:BY+BZ:BZ + CA:CA -> 48 | CC14: =ROUND(0.7 + (BR:BR* 0.2) + (BS:BS * 0.1),3) -> 0.856 | CD14: =ROUND(CB:CB* CC:CC, 2) -> 41.09 | CE14: =ROUND( 1 - ( (D:D * 0.25) + (E:E* 0.2) + (F:F* 0.15) + (G:G* 0.1) ) * AQ:AQ, 3 ) -> 0.925 | CF14: =ROUND( CD:CD* CE:CE, 2 ) -> 38.01 | CG14: =RANK(CF14,CF:CF) -> 50
A15: 1202550 | B15: Jake Fraser-McGurk | C15: Batsman | D15: 1 | E15: 0 | F15: 0 | G15: 0 | H15: 9 | I15: 9 | J15: =ROUND((K15 - MIN($K$2:$K$98)) / (MAX($K$2:$K$98) - MIN($K$2:$K$98)), 1) -> 0.2 | K15: 330 | L15: 0.2 | M15: 0 | N15: Middle | O15: 1 | P15: Australia | Q15: 1 | R15: 21 | S15: 84 | T15: 36.67 | U15: =ROUND((T15 - MIN(T$2:T$98)) / (MAX(T$2:T$98) - MIN(T$2:T$98)), 1) -> 0.7 | V15: 234.04 | W15: =ROUND((V15 - MIN(V$2:V$98)) / (MAX(V$2:V$98) - MIN(V$2:V$98)), 1) -> 1 | X15: 32 | Y15: 28 | Z15: 0 | AA15: 4 | AB15: 12.5 | AC15: =IF(AB15>AD15, 3,IF(AB15<AD15, 1, 2)) -> 3 | AD15: 2 | AE15: 0.5 | AF15: 0.0125 | AG15: 7.5 | AH15: 0.083 | AI15: 50 | AJ15: =ROUND((AI15 - MIN(AI$2:AI$98)) / (MAX(AI$2:AI$98) - MIN(AI$2:AI$98)), 1) -> 0.6 | AK15: 0 | AL15: 0 | AM15: 0 | AN15: 0 | AO15: =ROUND((AP15 - MIN($AP$2:$AP2063)) / (MAX($AP$2:$AP2063) - MIN($AP$2:$AP2063)), 1) -> 0 | AP15: 0 | AQ15: =ROUND((AR15 - MIN($AR$2:$AR2063)) / (MAX($AR$2:$AR2063) - MIN($AR$2:$AR2063)), 1) -> 0.2 | AR15: 3 | AS15: 0 | AT15: 0 | AU15: 0 | AV15: 0 | AW15: 45 | AX15: 0.5 | AY15: 0 | AZ15: =(AP15 - MIN($AP$2:$AP$964)) / (MAX($AP$2:$AP$964) - MIN($AP$2:$AP$964)) -> 0 | BA15: 0 | BB15: 0 | BC15: 0 | BD15: 0 | BE15: 7.5 | BF15: =ROUND((BE15 - MIN(BE$2:BE$174)) / (MAX(BE$2:BE$174) - MIN(BE$2:BE$174)), 1) -> 0.4 | BG15: =IF(AND(K15>=800,V15>=145),3,IF(K15>=400,1,2)) -> 2 | BH15: 7 | BI15: =ROUND((BH15 - MIN(BH$2:BH$174)) / (MAX(BH$2:BH$174) - MIN(BH$2:BH$174)), 1) -> 0.3 | BJ15: 6 | BK15: 0.57 | BL15: 8 | BM15: 0.67 | BN15: 0 | BO15: 0 | BP15: =ROUND((0.35 * L15) + (0.25 * W15) + (0.15 * U15) + (0.15 * BF15) + (0.1 * AJ15), 1) -> 0.5 | BQ15: 0 | BR15: 0 | BS15: =(0.45*L15 + 0.35*M15 + 0.12*AJ15 + 0.08*BF15) * (1 - BR15) -> 0.194 | BT15: 0 | BU15: 0 | BV15: 42.55 | BW15: 0.051 | BX15: =D15 * ( BP15*0.4 + L15*0.25 + W15*0.15 + AX15*0.1 + BF15*0.1 ) * 100 -> 49 | BY15: =E:E*(BQ:BQ*0.35+AT:AT*0.3+AV:AV*0.15+AN:AN*0.1+AO:AO*0.1)*100 -> 0 | BZ15: =ROUND(IF(N(F15)=1, MAX(0, ( (N(BN15)/18)*0.6 + (N(BF15)/10)*0.25 + N(AX15)*0.15 ) * 100 ), 0 ),3) -> 0 | CA15: =ROUND(G:G*(BO:BO*0.45+AZ:AZ*0.3+BB:BB*0.15+BF:BF*0.1)*100,3) -> 0 | CB15: =BX:BX+BY:BY+BZ:BZ + CA:CA -> 49 | CC15: =ROUND(0.7 + (BR:BR* 0.2) + (BS:BS * 0.1),3) -> 0.719 | CD15: =ROUND(CB:CB* CC:CC, 2) -> 35.23 | CE15: =ROUND( 1 - ( (D:D * 0.25) + (E:E* 0.2) + (F:F* 0.15) + (G:G* 0.1) ) * AQ:AQ, 3 ) -> 0.95 | CF15: =ROUND( CD:CD* CE:CE, 2 ) -> 33.47 | CG15: =RANK(CF15,CF:CF) -> 69
A16: 422108 | B16: Lokesh Rahul | C16: Batsman | D16: 1 | E16: 0 | F16: 0 | G16: 0 | H16: 23 | I16: 23 | J16: =ROUND((K16 - MIN($K$2:$K$98)) / (MAX($K$2:$K$98) - MIN($K$2:$K$98)), 1) -> 0.6 | K16: 794 | L16: 0.3 | M16: 0 | N16: Middle | O16: 1 | P16: India | Q16: 0 | R16: 31 | S16: 82 | T16: 36.09 | U16: =ROUND((T16 - MIN(T$2:T$98)) / (MAX(T$2:T$98) - MIN(T$2:T$98)), 1) -> 0.7 | V16: 127.24 | W16: =ROUND((V16 - MIN(V$2:V$98)) / (MAX(V$2:V$98) - MIN(V$2:V$98)), 1) -> 0.5 | X16: 73 | Y16: 23 | Z16: 0 | AA16: 6 | AB16: 12.5 | AC16: =IF(AB16>AD16, 3,IF(AB16<AD16, 1, 2)) -> 3 | AD16: 2 | AE16: 0.7 | AF16: 0.0175 | AG16: 7 | AH16: 0.135 | AI16: 75 | AJ16: =ROUND((AI16 - MIN(AI$2:AI$98)) / (MAX(AI$2:AI$98) - MIN(AI$2:AI$98)), 1) -> 0.9 | AK16: 0 | AL16: 0 | AM16: 0 | AN16: 0 | AO16: =ROUND((AP16 - MIN($AP$2:$AP2064)) / (MAX($AP$2:$AP2064) - MIN($AP$2:$AP2064)), 1) -> 0 | AP16: 0 | AQ16: =ROUND((AR16 - MIN($AR$2:$AR2064)) / (MAX($AR$2:$AR2064) - MIN($AR$2:$AR2064)), 1) -> 0.4 | AR16: 4.5 | AS16: 0 | AT16: 0 | AU16: 0 | AV16: 0 | AW16: 37 | AX16: 0.4 | AY16: 0 | AZ16: =(AP16 - MIN($AP$2:$AP$964)) / (MAX($AP$2:$AP$964) - MIN($AP$2:$AP$964)) -> 0 | BA16: 0 | BB16: 0 | BC16: 0 | BD16: 0 | BE16: 7 | BF16: =ROUND((BE16 - MIN(BE$2:BE$174)) / (MAX(BE$2:BE$174) - MIN(BE$2:BE$174)), 1) -> 0.3 | BG16: =IF(AND(K16>=800,V16>=145),3,IF(K16>=400,1,2)) -> 1 | BH16: 6 | BI16: =ROUND((BH16 - MIN(BH$2:BH$174)) / (MAX(BH$2:BH$174) - MIN(BH$2:BH$174)), 1) -> 0 | BJ16: 8 | BK16: 0.86 | BL16: 7 | BM16: 0.33 | BN16: 0 | BO16: 0 | BP16: =ROUND((0.35 * L16) + (0.25 * W16) + (0.15 * U16) + (0.15 * BF16) + (0.1 * AJ16), 1) -> 0.5 | BQ16: 0 | BR16: 0 | BS16: =(0.45*L16 + 0.35*M16 + 0.12*AJ16 + 0.08*BF16) * (1 - BR16) -> 0.267 | BT16: 0 | BU16: 0 | BV16: 54.7 | BW16: 0.065 | BX16: =D16 * ( BP16*0.4 + L16*0.25 + W16*0.15 + AX16*0.1 + BF16*0.1 ) * 100 -> 42 | BY16: =E:E*(BQ:BQ*0.35+AT:AT*0.3+AV:AV*0.15+AN:AN*0.1+AO:AO*0.1)*100 -> 0 | BZ16: =ROUND(IF(N(F16)=1, MAX(0, ( (N(BN16)/18)*0.6 + (N(BF16)/10)*0.25 + N(AX16)*0.15 ) * 100 ), 0 ),3) -> 0 | CA16: =ROUND(G:G*(BO:BO*0.45+AZ:AZ*0.3+BB:BB*0.15+BF:BF*0.1)*100,3) -> 0 | CB16: =BX:BX+BY:BY+BZ:BZ + CA:CA -> 42 | CC16: =ROUND(0.7 + (BR:BR* 0.2) + (BS:BS * 0.1),3) -> 0.727 | CD16: =ROUND(CB:CB* CC:CC, 2) -> 30.53 | CE16: =ROUND( 1 - ( (D:D * 0.25) + (E:E* 0.2) + (F:F* 0.15) + (G:G* 0.1) ) * AQ:AQ, 3 ) -> 0.9 | CF16: =ROUND( CD:CD* CE:CE, 2 ) -> 27.48 | CG16: =RANK(CF16,CF:CF) -> 116
A17: 318845 | B17: Rilee Rossouw | C17: Batsman | D17: 1 | E17: 0 | F17: 0 | G17: 0 | H17: 17 | I17: 17 | J17: =ROUND((K17 - MIN($K$2:$K$98)) / (MAX($K$2:$K$98) - MIN($K$2:$K$98)), 1) -> 0.3 | K17: 420 | L17: 0.3 | M17: 0 | N17: Middle | O17: 2 | P17: South Africa | Q17: 1 | R17: 34 | S17: 82 | T17: 28 | U17: =ROUND((T17 - MIN(T$2:T$98)) / (MAX(T$2:T$98) - MIN(T$2:T$98)), 1) -> 0.5 | V17: 163.42 | W17: =ROUND((V17 - MIN(V$2:V$98)) / (MAX(V$2:V$98) - MIN(V$2:V$98)), 1) -> 0.7 | X17: 42 | Y17: 22 | Z17: 0 | AA17: 2 | AB17: 12.5 | AC17: =IF(AB17>AD17, 3,IF(AB17<AD17, 1, 2)) -> 3 | AD17: 2 | AE17: 0.6 | AF17: 0.015 | AG17: 6.5 | AH17: 0.121 | AI17: 65 | AJ17: =ROUND((AI17 - MIN(AI$2:AI$98)) / (MAX(AI$2:AI$98) - MIN(AI$2:AI$98)), 1) -> 0.8 | AK17: 0 | AL17: 0 | AM17: 0 | AN17: 0 | AO17: =ROUND((AP17 - MIN($AP$2:$AP2065)) / (MAX($AP$2:$AP2065) - MIN($AP$2:$AP2065)), 1) -> 0 | AP17: 0 | AQ17: =ROUND((AR17 - MIN($AR$2:$AR2065)) / (MAX($AR$2:$AR2065) - MIN($AR$2:$AR2065)), 1) -> 0.5 | AR17: 5 | AS17: 0 | AT17: 0 | AU17: 0 | AV17: 0 | AW17: 50 | AX17: 0.5 | AY17: 0 | AZ17: =(AP17 - MIN($AP$2:$AP$964)) / (MAX($AP$2:$AP$964) - MIN($AP$2:$AP$964)) -> 0 | BA17: 0 | BB17: 0 | BC17: 0 | BD17: 0 | BE17: 6.5 | BF17: =ROUND((BE17 - MIN(BE$2:BE$174)) / (MAX(BE$2:BE$174) - MIN(BE$2:BE$174)), 1) -> 0.1 | BG17: =IF(AND(K17>=800,V17>=145),3,IF(K17>=400,1,2)) -> 1 | BH17: 6 | BI17: =ROUND((BH17 - MIN(BH$2:BH$174)) / (MAX(BH$2:BH$174) - MIN(BH$2:BH$174)), 1) -> 0 | BJ17: 7 | BK17: 0.71 | BL17: 7 | BM17: 0.33 | BN17: 0 | BO17: 0 | BP17: =ROUND((0.35 * L17) + (0.25 * W17) + (0.15 * U17) + (0.15 * BF17) + (0.1 * AJ17), 1) -> 0.5 | BQ17: 0 | BR17: 0 | BS17: =(0.45*L17 + 0.35*M17 + 0.12*AJ17 + 0.08*BF17) * (1 - BR17) -> 0.239 | BT17: 0 | BU17: 0 | BV17: 47.85 | BW17: 0.057 | BX17: =D17 * ( BP17*0.4 + L17*0.25 + W17*0.15 + AX17*0.1 + BF17*0.1 ) * 100 -> 44 | BY17: =E:E*(BQ:BQ*0.35+AT:AT*0.3+AV:AV*0.15+AN:AN*0.1+AO:AO*0.1)*100 -> 0 | BZ17: =ROUND(IF(N(F17)=1, MAX(0, ( (N(BN17)/18)*0.6 + (N(BF17)/10)*0.25 + N(AX17)*0.15 ) * 100 ), 0 ),3) -> 0 | CA17: =ROUND(G:G*(BO:BO*0.45+AZ:AZ*0.3+BB:BB*0.15+BF:BF*0.1)*100,3) -> 0 | CB17: =BX:BX+BY:BY+BZ:BZ + CA:CA -> 44 | CC17: =ROUND(0.7 + (BR:BR* 0.2) + (BS:BS * 0.1),3) -> 0.724 | CD17: =ROUND(CB:CB* CC:CC, 2) -> 31.86 | CE17: =ROUND( 1 - ( (D:D * 0.25) + (E:E* 0.2) + (F:F* 0.15) + (G:G* 0.1) ) * AQ:AQ, 3 ) -> 0.875 | CF17: =ROUND( CD:CD* CE:CE, 2 ) -> 27.88 | CG17: =RANK(CF17,CF:CF) -> 113
A18: 1070183 | B18: Sanju Samson | C18: Batsman | D18: 1 | E18: 0 | F18: 0 | G18: 1 | H18: 31 | I18: 31 | J18: =ROUND((K18 - MIN($K$2:$K$98)) / (MAX($K$2:$K$98) - MIN($K$2:$K$98)), 1) -> 0.7 | K18: 930 | L18: 0.4 | M18: 0 | N18: Middle | O18: 2 | P18: India | Q18: 0 | R18: 29 | S18: 86 | T18: 37.2 | U18: =ROUND((T18 - MIN(T$2:T$98)) / (MAX(T$2:T$98) - MIN(T$2:T$98)), 1) -> 0.7 | V18: 151.47 | W18: =ROUND((V18 - MIN(V$2:V$98)) / (MAX(V$2:V$98) - MIN(V$2:V$98)), 1) -> 0.6 | X18: 48 | Y18: 50 | Z18: 0 | AA18: 8 | AB18: 12.5 | AC18: =IF(AB18>AD18, 3,IF(AB18<AD18, 1, 2)) -> 3 | AD18: 0 | AE18: 0.6 | AF18: 0.015 | AG18: 8 | AH18: 0.2 | AI18: 70 | AJ18: =ROUND((AI18 - MIN(AI$2:AI$98)) / (MAX(AI$2:AI$98) - MIN(AI$2:AI$98)), 1) -> 0.8 | AK18: 1 | AL18: 0 | AM18: 0 | AN18: 0 | AO18: =ROUND((AP18 - MIN($AP$2:$AP2066)) / (MAX($AP$2:$AP2066) - MIN($AP$2:$AP2066)), 1) -> 0 | AP18: 0 | AQ18: =ROUND((AR18 - MIN($AR$2:$AR2066)) / (MAX($AR$2:$AR2066) - MIN($AR$2:$AR2066)), 1) -> 0.3 | AR18: 4 | AS18: 0 | AT18: 0 | AU18: 0 | AV18: 0 | AW18: 48 | AX18: 0.5 | AY18: 9 | AZ18: 0.56 | BA18: 11 | BB18: 0.23 | BC18: 0 | BD18: 0 | BE18: 8 | BF18: =ROUND((BE18 - MIN(BE$2:BE$174)) / (MAX(BE$2:BE$174) - MIN(BE$2:BE$174)), 1) -> 0.5 | BG18: =IF(AND(K18>=800,V18>=145),3,IF(K18>=400,1,2)) -> 3 | BH18: 6 | BI18: =ROUND((BH18 - MIN(BH$2:BH$174)) / (MAX(BH$2:BH$174) - MIN(BH$2:BH$174)), 1) -> 0 | BJ18: 8 | BK18: 0.86 | BL18: 6 | BM18: 0 | BN18: 0 | BO18: 0.4 | BP18: =ROUND((0.35 * L18) + (0.25 * W18) + (0.15 * U18) + (0.15 * BF18) + (0.1 * AJ18), 1) -> 0.6 | BQ18: 0 | BR18: 0.72 | BS18: =(0.45*L18 + 0.35*M18 + 0.12*AJ18 + 0.08*BF18) * (1 - BR18) -> 0.08848 | BT18: 0 | BU18: 0 | BV18: 62.8 | BW18: 0.073 | BX18: =D18 * ( BP18*0.4 + L18*0.25 + W18*0.15 + AX18*0.1 + BF18*0.1 ) * 100 -> 53 | BY18: =E:E*(BQ:BQ*0.35+AT:AT*0.3+AV:AV*0.15+AN:AN*0.1+AO:AO*0.1)*100 -> 0 | BZ18: =ROUND(IF(N(F18)=1, MAX(0, ( (N(BN18)/18)*0.6 + (N(BF18)/10)*0.25 + N(AX18)*0.15 ) * 100 ), 0 ),3) -> 0 | CA18: =ROUND(G:G*(BO:BO*0.45+AZ:AZ*0.3+BB:BB*0.15+BF:BF*0.1)*100,3) -> 43.25 | CB18: =BX:BX+BY:BY+BZ:BZ + CA:CA -> 96.25 | CC18: =ROUND(0.7 + (BR:BR* 0.2) + (BS:BS * 0.1),3) -> 0.853 | CD18: =ROUND(CB:CB* CC:CC, 2) -> 82.1 | CE18: =ROUND( 1 - ( (D:D * 0.25) + (E:E* 0.2) + (F:F* 0.15) + (G:G* 0.1) ) * AQ:AQ, 3 ) -> 0.895 | CF18: =ROUND( CD:CD* CE:CE, 2 ) -> 73.48 | CG18: =RANK(CF18,CF:CF) -> 15
A19: 1159186 | B19: Tilak Varma | C19: Batsman | D19: 1 | E19: 0 | F19: 0 | G19: 0 | H19: 24 | I19: 24 | J19: =ROUND((K19 - MIN($K$2:$K$98)) / (MAX($K$2:$K$98) - MIN($K$2:$K$98)), 1) -> 0.5 | K19: 759 | L19: 0.4 | M19: 0 | N19: Middle | O19: 2 | P19: India | Q19: 0 | R19: 21 | S19: 84 | T19: 42.17 | U19: =ROUND((T19 - MIN(T$2:T$98)) / (MAX(T$2:T$98) - MIN(T$2:T$98)), 1) -> 0.8 | V19: 155.85 | W19: =ROUND((V19 - MIN(V$2:V$98)) / (MAX(V$2:V$98) - MIN(V$2:V$98)), 1) -> 0.6 | X19: 61 | Y19: 42 | Z19: 0 | AA19: 4 | AB19: 11.75 | AC19: =IF(AB19>AD19, 3,IF(AB19<AD19, 1, 2)) -> 3 | AD19: 0.5 | AE19: 0.6 | AF19: 0.015 | AG19: 7.5 | AH19: 0.019 | AI19: 60 | AJ19: =ROUND((AI19 - MIN(AI$2:AI$98)) / (MAX(AI$2:AI$98) - MIN(AI$2:AI$98)), 1) -> 0.7 | AK19: 0 | AL19: 0 | AM19: 0 | AN19: 0 | AO19: =ROUND((AP19 - MIN($AP$2:$AP2067)) / (MAX($AP$2:$AP2067) - MIN($AP$2:$AP2067)), 1) -> 0 | AP19: 0 | AQ19: =ROUND((AR19 - MIN($AR$2:$AR2067)) / (MAX($AR$2:$AR2067) - MIN($AR$2:$AR2067)), 1) -> 0.1 | AR19: 2.5 | AS19: 0 | AT19: 0 | AU19: 0 | AV19: 0 | AW19: 33 | AX19: 0.3 | AY19: 0 | AZ19: =(AP19 - MIN($AP$2:$AP$964)) / (MAX($AP$2:$AP$964) - MIN($AP$2:$AP$964)) -> 0 | BA19: 0 | BB19: 0 | BC19: 0 | BD19: 0 | BE19: 7.5 | BF19: =ROUND((BE19 - MIN(BE$2:BE$174)) / (MAX(BE$2:BE$174) - MIN(BE$2:BE$174)), 1) -> 0.4 | BG19: =IF(AND(K19>=800,V19>=145),3,IF(K19>=400,1,2)) -> 1 | BH19: 6 | BI19: =ROUND((BH19 - MIN(BH$2:BH$174)) / (MAX(BH$2:BH$174) - MIN(BH$2:BH$174)), 1) -> 0 | BJ19: 8 | BK19: 0.86 | BL19: 8 | BM19: 0.67 | BN19: 0 | BO19: 0 | BP19: =ROUND((0.35 * L19) + (0.25 * W19) + (0.15 * U19) + (0.15 * BF19) + (0.1 * AJ19), 1) -> 0.5 | BQ19: 0 | BR19: 0.61 | BS19: =(0.45*L19 + 0.35*M19 + 0.12*AJ19 + 0.08*BF19) * (1 - BR19) -> 0.11544 | BT19: 0 | BU19: 0 | BV19: 49 | BW19: 0.058 | BX19: =D19 * ( BP19*0.4 + L19*0.25 + W19*0.15 + AX19*0.1 + BF19*0.1 ) * 100 -> 46 | BY19: =E:E*(BQ:BQ*0.35+AT:AT*0.3+AV:AV*0.15+AN:AN*0.1+AO:AO*0.1)*100 -> 0 | BZ19: =ROUND(IF(N(F19)=1, MAX(0, ( (N(BN19)/18)*0.6 + (N(BF19)/10)*0.25 + N(AX19)*0.15 ) * 100 ), 0 ),3) -> 0 | CA19: =ROUND(G:G*(BO:BO*0.45+AZ:AZ*0.3+BB:BB*0.15+BF:BF*0.1)*100,3) -> 0 | CB19: =BX:BX+BY:BY+BZ:BZ + CA:CA -> 46 | CC19: =ROUND(0.7 + (BR:BR* 0.2) + (BS:BS * 0.1),3) -> 0.834 | CD19: =ROUND(CB:CB* CC:CC, 2) -> 38.36 | CE19: =ROUND( 1 - ( (D:D * 0.25) + (E:E* 0.2) + (F:F* 0.15) + (G:G* 0.1) ) * AQ:AQ, 3 ) -> 0.975 | CF19: =ROUND( CD:CD* CE:CE, 2 ) -> 37.4 | CG19: =RANK(CF19,CF:CF) -> 52
A20: 1168045 | B20: Marcus Stoinis | C20: Batsman | D20: 1 | E20: 0 | F20: 0 | G20: 0 | H20: 29 | I20: 29 | J20: =ROUND((K20 - MIN($K$2:$K$98)) / (MAX($K$2:$K$98) - MIN($K$2:$K$98)), 1) -> 0.6 | K20: 796 | L20: 0.4 | M20: 0 | N20: Finisher | O20: 3 | P20: Australia | Q20: 1 | R20: 34 | S20: 124 | T20: 31.84 | U20: =ROUND((T20 - MIN(T$2:T$98)) / (MAX(T$2:T$98) - MIN(T$2:T$98)), 1) -> 0.6 | V20: 148.79 | W20: =ROUND((V20 - MIN(V$2:V$98)) / (MAX(V$2:V$98) - MIN(V$2:V$98)), 1) -> 0.6 | X20: 67 | Y20: 43 | Z20: 1 | AA20: 5 | AB20: 11 | AC20: =IF(AB20>AD20, 3,IF(AB20<AD20, 1, 2)) -> 3 | AD20: 2 | AE20: 0.7 | AF20: 0.0175 | AG20: 8 | AH20: 0.25 | AI20: 65 | AJ20: =ROUND((AI20 - MIN(AI$2:AI$98)) / (MAX(AI$2:AI$98) - MIN(AI$2:AI$98)), 1) -> 0.8 | AK20: 0 | AL20: 0 | AM20: 0 | AN20: 0 | AO20: =ROUND((AP20 - MIN($AP$2:$AP2068)) / (MAX($AP$2:$AP2068) - MIN($AP$2:$AP2068)), 1) -> 0 | AP20: 0 | AQ20: =ROUND((AR20 - MIN($AR$2:$AR2068)) / (MAX($AR$2:$AR2068) - MIN($AR$2:$AR2068)), 1) -> 0.6 | AR20: 5.5 | AS20: 0 | AT20: 0 | AU20: 0 | AV20: 0 | AW20: 42 | AX20: 0.4 | AY20: 0 | AZ20: =(AP20 - MIN($AP$2:$AP$964)) / (MAX($AP$2:$AP$964) - MIN($AP$2:$AP$964)) -> 0 | BA20: 0 | BB20: 0 | BC20: 0 | BD20: 0 | BE20: 8 | BF20: =ROUND((BE20 - MIN(BE$2:BE$174)) / (MAX(BE$2:BE$174) - MIN(BE$2:BE$174)), 1) -> 0.5 | BG20: =IF(AND(K20>=800,V20>=145),3,IF(K20>=400,1,2)) -> 1 | BH20: 7 | BI20: =ROUND((BH20 - MIN(BH$2:BH$174)) / (MAX(BH$2:BH$174) - MIN(BH$2:BH$174)), 1) -> 0.3 | BJ20: 7 | BK20: 0.71 | BL20: 7 | BM20: 0.33 | BN20: 0 | BO20: 0 | BP20: =ROUND((0.35 * L20) + (0.25 * W20) + (0.15 * U20) + (0.15 * BF20) + (0.1 * AJ20), 1) -> 0.5 | BQ20: 0 | BR20: 0 | BS20: =(0.45*L20 + 0.35*M20 + 0.12*AJ20 + 0.08*BF20) * (1 - BR20) -> 0.316 | BT20: 0 | BU20: 0 | BV20: 53.55 | BW20: 0.063 | BX20: =D20 * ( BP20*0.4 + L20*0.25 + W20*0.15 + AX20*0.1 + BF20*0.1 ) * 100 -> 48 | BY20: =E:E*(BQ:BQ*0.35+AT:AT*0.3+AV:AV*0.15+AN:AN*0.1+AO:AO*0.1)*100 -> 0 | BZ20: =ROUND(IF(N(F20)=1, MAX(0, ( (N(BN20)/18)*0.6 + (N(BF20)/10)*0.25 + N(AX20)*0.15 ) * 100 ), 0 ),3) -> 0 | CA20: =ROUND(G:G*(BO:BO*0.45+AZ:AZ*0.3+BB:BB*0.15+BF:BF*0.1)*100,3) -> 0 | CB20: =BX:BX+BY:BY+BZ:BZ + CA:CA -> 48 | CC20: =ROUND(0.7 + (BR:BR* 0.2) + (BS:BS * 0.1),3) -> 0.732 | CD20: =ROUND(CB:CB* CC:CC, 2) -> 35.14 | CE20: =ROUND( 1 - ( (D:D * 0.25) + (E:E* 0.2) + (F:F* 0.15) + (G:G* 0.1) ) * AQ:AQ, 3 ) -> 0.85 | CF20: =ROUND( CD:CD* CE:CE, 2 ) -> 29.87 | CG20: =RANK(CF20,CF:CF) -> 97
A21: 714451 | B21: Shivam Dube | C21: Batsman | D21: 1 | E21: 0 | F21: 0 | G21: 0 | H21: 28 | I21: 27 | J21: =ROUND((K21 - MIN($K$2:$K$98)) / (MAX($K$2:$K$98) - MIN($K$2:$K$98)), 1) -> 0.6 | K21: 814 | L21: 0.1 | M21: 0 | N21: Middle | O21: 3 | P21: India | Q21: 0 | R21: 28 | S21: 66 | T21: 37 | U21: =ROUND((T21 - MIN(T$2:T$98)) / (MAX(T$2:T$98) - MIN(T$2:T$98)), 1) -> 0.7 | V21: 160.24 | W21: =ROUND((V21 - MIN(V$2:V$98)) / (MAX(V$2:V$98) - MIN(V$2:V$98)), 1) -> 0.7 | X21: 40 | Y21: 63 | Z21: 0 | AA21: 6 | AB21: 4 | AC21: =IF(AB21>AD21, 3,IF(AB21<AD21, 1, 2)) -> 3 | AD21: 0.5 | AE21: 0.6 | AF21: 0.015 | AG21: 8 | AH21: 1 | AI21: 55 | AJ21: =ROUND((AI21 - MIN(AI$2:AI$98)) / (MAX(AI$2:AI$98) - MIN(AI$2:AI$98)), 1) -> 0.6 | AK21: 0 | AL21: 0 | AM21: 0 | AN21: 0 | AO21: =ROUND((AP21 - MIN($AP$2:$AP2069)) / (MAX($AP$2:$AP2069) - MIN($AP$2:$AP2069)), 1) -> 0 | AP21: 0 | AQ21: =ROUND((AR21 - MIN($AR$2:$AR2069)) / (MAX($AR$2:$AR2069) - MIN($AR$2:$AR2069)), 1) -> 0.4 | AR21: 4.5 | AS21: 0 | AT21: 0 | AU21: 0 | AV21: 0 | AW21: 40 | AX21: 0.4 | AY21: 0 | AZ21: =(AP21 - MIN($AP$2:$AP$964)) / (MAX($AP$2:$AP$964) - MIN($AP$2:$AP$964)) -> 0 | BA21: 0 | BB21: 0 | BC21: 0 | BD21: 0 | BE21: 8 | BF21: =ROUND((BE21 - MIN(BE$2:BE$174)) / (MAX(BE$2:BE$174) - MIN(BE$2:BE$174)), 1) -> 0.5 | BG21: =IF(AND(K21>=800,V21>=145),3,IF(K21>=400,1,2)) -> 3 | BH21: 6 | BI21: =ROUND((BH21 - MIN(BH$2:BH$174)) / (MAX(BH$2:BH$174) - MIN(BH$2:BH$174)), 1) -> 0 | BJ21: 8 | BK21: 0.86 | BL21: 8 | BM21: 0.67 | BN21: 0 | BO21: 0 | BP21: =ROUND((0.35 * L21) + (0.25 * W21) + (0.15 * U21) + (0.15 * BF21) + (0.1 * AJ21), 1) -> 0.5 | BQ21: 0 | BR21: 0.69 | BS21: =(0.45*L21 + 0.35*M21 + 0.12*AJ21 + 0.08*BF21) * (1 - BR21) -> 0.04867 | BT21: 0 | BU21: 0 | BV21: 51.3 | BW21: 0.061 | BX21: =D21 * ( BP21*0.4 + L21*0.25 + W21*0.15 + AX21*0.1 + BF21*0.1 ) * 100 -> 42 | BY21: =E:E*(BQ:BQ*0.35+AT:AT*0.3+AV:AV*0.15+AN:AN*0.1+AO:AO*0.1)*100 -> 0 | BZ21: =ROUND(IF(N(F21)=1, MAX(0, ( (N(BN21)/18)*0.6 + (N(BF21)/10)*0.25 + N(AX21)*0.15 ) * 100 ), 0 ),3) -> 0 | CA21: =ROUND(G:G*(BO:BO*0.45+AZ:AZ*0.3+BB:BB*0.15+BF:BF*0.1)*100,3) -> 0 | CB21: =BX:BX+BY:BY+BZ:BZ + CA:CA -> 42 | CC21: =ROUND(0.7 + (BR:BR* 0.2) + (BS:BS * 0.1),3) -> 0.843 | CD21: =ROUND(CB:CB* CC:CC, 2) -> 35.41 | CE21: =ROUND( 1 - ( (D:D * 0.25) + (E:E* 0.2) + (F:F* 0.15) + (G:G* 0.1) ) * AQ:AQ, 3 ) -> 0.9 | CF21: =ROUND( CD:CD* CE:CE, 2 ) -> 31.87 | CG21: =RANK(CF21,CF:CF) -> 80
A22: 308967 | B22: Jos Buttler | C22: Batsman | D22: 1 | E22: 0 | F22: 0 | G22: 0 | H22: 27 | I22: 28 | J22: =ROUND((K22 - MIN($K$2:$K$98)) / (MAX($K$2:$K$98) - MIN($K$2:$K$98)), 1) -> 0.6 | K22: 896 | L22: 0.4 | M22: 0 | N22: Finisher | O22: 1 | P22: England | Q22: 1 | R22: 33 | S22: 107 | T22: 37.33 | U22: =ROUND((T22 - MIN(T$2:T$98)) / (MAX(T$2:T$98) - MIN(T$2:T$98)), 1) -> 0.7 | V22: 141.77 | W22: =ROUND((V22 - MIN(V$2:V$98)) / (MAX(V$2:V$98) - MIN(V$2:V$98)), 1) -> 0.6 | X22: 93 | Y22: 32 | Z22: 3 | AA22: 4 | AB22: 15.75 | AC22: =IF(AB22>AD22, 3,IF(AB22<AD22, 1, 2)) -> 3 | AD22: 2 | AE22: 0.7 | AF22: 0.0175 | AG22: 7.5 | AH22: 0.013 | AI22: 80 | AJ22: =ROUND((AI22 - MIN(AI$2:AI$98)) / (MAX(AI$2:AI$98) - MIN(AI$2:AI$98)), 1) -> 0.9 | AK22: 0 | AL22: 0 | AM22: 0 | AN22: 0 | AO22: =ROUND((AP22 - MIN($AP$2:$AP2070)) / (MAX($AP$2:$AP2070) - MIN($AP$2:$AP2070)), 1) -> 0 | AP22: 0 | AQ22: =ROUND((AR22 - MIN($AR$2:$AR2070)) / (MAX($AR$2:$AR2070) - MIN($AR$2:$AR2070)), 1) -> 0.5 | AR22: 5 | AS22: 0 | AT22: 0 | AU22: 0 | AV22: 0 | AW22: 59 | AX22: 0.6 | AY22: 0 | AZ22: =(AP22 - MIN($AP$2:$AP$964)) / (MAX($AP$2:$AP$964) - MIN($AP$2:$AP$964)) -> 0 | BA22: 0 | BB22: 0 | BC22: 0 | BD22: 0 | BE22: 7 | BF22: =ROUND((BE22 - MIN(BE$2:BE$174)) / (MAX(BE$2:BE$174) - MIN(BE$2:BE$174)), 1) -> 0.3 | BG22: =IF(AND(K22>=800,V22>=145),3,IF(K22>=400,1,2)) -> 1 | BH22: 7 | BI22: =ROUND((BH22 - MIN(BH$2:BH$174)) / (MAX(BH$2:BH$174) - MIN(BH$2:BH$174)), 1) -> 0.3 | BJ22: 8 | BK22: 0.86 | BL22: 8 | BM22: 0.67 | BN22: 0 | BO22: 0 | BP22: =ROUND((0.35 * L22) + (0.25 * W22) + (0.15 * U22) + (0.15 * BF22) + (0.1 * AJ22), 1) -> 0.5 | BQ22: 0 | BR22: 0.81 | BS22: =(0.45*L22 + 0.35*M22 + 0.12*AJ22 + 0.08*BF22) * (1 - BR22) -> 0.05928 | BT22: 0 | BU22: 0 | BV22: 56.7 | BW22: 0.067 | BX22: =D22 * ( BP22*0.4 + L22*0.25 + W22*0.15 + AX22*0.1 + BF22*0.1 ) * 100 -> 48 | BY22: =E:E*(BQ:BQ*0.35+AT:AT*0.3+AV:AV*0.15+AN:AN*0.1+AO:AO*0.1)*100 -> 0 | BZ22: =ROUND(IF(N(F22)=1, MAX(0, ( (N(BN22)/18)*0.6 + (N(BF22)/10)*0.25 + N(AX22)*0.15 ) * 100 ), 0 ),3) -> 0 | CA22: =ROUND(G:G*(BO:BO*0.45+AZ:AZ*0.3+BB:BB*0.15+BF:BF*0.1)*100,3) -> 0 | CB22: =BX:BX+BY:BY+BZ:BZ + CA:CA -> 48 | CC22: =ROUND(0.7 + (BR:BR* 0.2) + (BS:BS * 0.1),3) -> 0.868 | CD22: =ROUND(CB:CB* CC:CC, 2) -> 41.66 | CE22: =ROUND( 1 - ( (D:D * 0.25) + (E:E* 0.2) + (F:F* 0.15) + (G:G* 0.1) ) * AQ:AQ, 3 ) -> 0.875 | CF22: =ROUND( CD:CD* CE:CE, 2 ) -> 36.45 | CG22: =RANK(CF22,CF:CF) -> 54
A23: 1119166 | B23: Venkatesh Iyer | C23: Batsman | D23: 1 | E23: 0 | F23: 0 | G23: 0 | H23: 27 | I23: 27 | J23: =ROUND((K23 - MIN($K$2:$K$98)) / (MAX($K$2:$K$98) - MIN($K$2:$K$98)), 1) -> 0.6 | K23: 774 | L23: 0.3 | M23: 0 | N23: Finisher | O23: 2 | P23: India | Q23: 0 | R23: 29 | S23: 104 | T23: 35.18 | U23: =ROUND((T23 - MIN(T$2:T$98)) / (MAX(T$2:T$98) - MIN(T$2:T$98)), 1) -> 0.6 | V23: 151.76 | W23: =ROUND((V23 - MIN(V$2:V$98)) / (MAX(V$2:V$98) - MIN(V$2:V$98)), 1) -> 0.6 | X23: 67 | Y23: 40 | Z23: 1 | AA23: 6 | AB23: 23.75 | AC23: =IF(AB23>AD23, 3,IF(AB23<AD23, 1, 2)) -> 3 | AD23: 2 | AE23: 0.6 | AF23: 0.015 | AG23: 6.5 | AH23: 0.137 | AI23: 65 | AJ23: =ROUND((AI23 - MIN(AI$2:AI$98)) / (MAX(AI$2:AI$98) - MIN(AI$2:AI$98)), 1) -> 0.8 | AK23: 0 | AL23: 0 | AM23: 0 | AN23: 0 | AO23: =ROUND((AP23 - MIN($AP$2:$AP2071)) / (MAX($AP$2:$AP2071) - MIN($AP$2:$AP2071)), 1) -> 0 | AP23: 0 | AQ23: =ROUND((AR23 - MIN($AR$2:$AR2071)) / (MAX($AR$2:$AR2071) - MIN($AR$2:$AR2071)), 1) -> 0.3 | AR23: 3.5 | AS23: 0 | AT23: 0 | AU23: 0 | AV23: 0 | AW23: 28 | AX23: 0.3 | AY23: 0 | AZ23: =(AP23 - MIN($AP$2:$AP$964)) / (MAX($AP$2:$AP$964) - MIN($AP$2:$AP$964)) -> 0 | BA23: 0 | BB23: 0 | BC23: 0 | BD23: 0 | BE23: 6.5 | BF23: =ROUND((BE23 - MIN(BE$2:BE$174)) / (MAX(BE$2:BE$174) - MIN(BE$2:BE$174)), 1) -> 0.1 | BG23: =IF(AND(K23>=800,V23>=145),3,IF(K23>=400,1,2)) -> 1 | BH23: 7 | BI23: =ROUND((BH23 - MIN(BH$2:BH$174)) / (MAX(BH$2:BH$174) - MIN(BH$2:BH$174)), 1) -> 0.3 | BJ23: 7 | BK23: 0.71 | BL23: 7 | BM23: 0.33 | BN23: 0 | BO23: 0 | BP23: =ROUND((0.35 * L23) + (0.25 * W23) + (0.15 * U23) + (0.15 * BF23) + (0.1 * AJ23), 1) -> 0.4 | BQ23: 0 | BR23: 0 | BS23: =(0.45*L23 + 0.35*M23 + 0.12*AJ23 + 0.08*BF23) * (1 - BR23) -> 0.239 | BT23: 0 | BU23: 0 | BV23: 48.85 | BW23: 0.058 | BX23: =D23 * ( BP23*0.4 + L23*0.25 + W23*0.15 + AX23*0.1 + BF23*0.1 ) * 100 -> 36.5 | BY23: =E:E*(BQ:BQ*0.35+AT:AT*0.3+AV:AV*0.15+AN:AN*0.1+AO:AO*0.1)*100 -> 0 | BZ23: =ROUND(IF(N(F23)=1, MAX(0, ( (N(BN23)/18)*0.6 + (N(BF23)/10)*0.25 + N(AX23)*0.15 ) * 100 ), 0 ),3) -> 0 | CA23: =ROUND(G:G*(BO:BO*0.45+AZ:AZ*0.3+BB:BB*0.15+BF:BF*0.1)*100,3) -> 0 | CB23: =BX:BX+BY:BY+BZ:BZ + CA:CA -> 36.5 | CC23: =ROUND(0.7 + (BR:BR* 0.2) + (BS:BS * 0.1),3) -> 0.724 | CD23: =ROUND(CB:CB* CC:CC, 2) -> 26.43 | CE23: =ROUND( 1 - ( (D:D * 0.25) + (E:E* 0.2) + (F:F* 0.15) + (G:G* 0.1) ) * AQ:AQ, 3 ) -> 0.925 | CF23: =ROUND( CD:CD* CE:CE, 2 ) -> 24.45 | CG23: =RANK(CF23,CF:CF) -> 130
A24: 219889 | B24: David Warner | C24: Batsman | D24: 1 | E24: 0 | F24: 0 | G24: 0 | H24: 22 | I24: 27 | J24: =ROUND((K24 - MIN($K$2:$K$98)) / (MAX($K$2:$K$98) - MIN($K$2:$K$98)), 1) -> 0.5 | K24: 684 | L24: 0.3 | M24: 0 | N24: Opener | O24: 1 | P24: Australia | Q24: 1 | R24: 37 | S24: 86 | T24: 31.09 | U24: =ROUND((T24 - MIN(T$2:T$98)) / (MAX(T$2:T$98) - MIN(T$2:T$98)), 1) -> 0.6 | V24: 132.3 | W24: =ROUND((V24 - MIN(V$2:V$98)) / (MAX(V$2:V$98) - MIN(V$2:V$98)), 1) -> 0.5 | X24: 86 | Y24: 20 | Z24: 0 | AA24: 7 | AB24: 6.25 | AC24: =IF(AB24>AD24, 3,IF(AB24<AD24, 1, 2)) -> 3 | AD24: 2 | AE24: 0.7 | AF24: 0.0175 | AG24: 7.5 | AH24: 0.014 | AI24: 75 | AJ24: =ROUND((AI24 - MIN(AI$2:AI$98)) / (MAX(AI$2:AI$98) - MIN(AI$2:AI$98)), 1) -> 0.9 | AK24: 0 | AL24: 0 | AM24: 0 | AN24: 0 | AO24: =ROUND((AP24 - MIN($AP$2:$AP2072)) / (MAX($AP$2:$AP2072) - MIN($AP$2:$AP2072)), 1) -> 0 | AP24: 0 | AQ24: =ROUND((AR24 - MIN($AR$2:$AR2072)) / (MAX($AR$2:$AR2072) - MIN($AR$2:$AR2072)), 1) -> 0.8 | AR24: 6.5 | AS24: 0 | AT24: 0 | AU24: 0 | AV24: 0 | AW24: 24 | AX24: 0.2 | AY24: 0 | AZ24: =(AP24 - MIN($AP$2:$AP$964)) / (MAX($AP$2:$AP$964) - MIN($AP$2:$AP$964)) -> 0 | BA24: 0 | BB24: 0 | BC24: 0 | BD24: 0 | BE24: 7 | BF24: =ROUND((BE24 - MIN(BE$2:BE$174)) / (MAX(BE$2:BE$174) - MIN(BE$2:BE$174)), 1) -> 0.3 | BG24: =IF(AND(K24>=800,V24>=145),3,IF(K24>=400,1,2)) -> 1 | BH24: 8 | BI24: =ROUND((BH24 - MIN(BH$2:BH$174)) / (MAX(BH$2:BH$174) - MIN(BH$2:BH$174)), 1) -> 0.7 | BJ24: 8 | BK24: 0.86 | BL24: 6 | BM24: 0 | BN24: 0 | BO24: 0 | BP24: =ROUND((0.35 * L24) + (0.25 * W24) + (0.15 * U24) + (0.15 * BF24) + (0.1 * AJ24), 1) -> 0.5 | BQ24: 0 | BR24: 0 | BS24: =(0.45*L24 + 0.35*M24 + 0.12*AJ24 + 0.08*BF24) * (1 - BR24) -> 0.267 | BT24: 0 | BU24: 0 | BV24: 64.7 | BW24: 0.075 | BX24: =D24 * ( BP24*0.4 + L24*0.25 + W24*0.15 + AX24*0.1 + BF24*0.1 ) * 100 -> 40 | BY24: =E:E*(BQ:BQ*0.35+AT:AT*0.3+AV:AV*0.15+AN:AN*0.1+AO:AO*0.1)*100 -> 0 | BZ24: =ROUND(IF(N(F24)=1, MAX(0, ( (N(BN24)/18)*0.6 + (N(BF24)/10)*0.25 + N(AX24)*0.15 ) * 100 ), 0 ),3) -> 0 | CA24: =ROUND(G:G*(BO:BO*0.45+AZ:AZ*0.3+BB:BB*0.15+BF:BF*0.1)*100,3) -> 0 | CB24: =BX:BX+BY:BY+BZ:BZ + CA:CA -> 40 | CC24: =ROUND(0.7 + (BR:BR* 0.2) + (BS:BS * 0.1),3) -> 0.727 | CD24: =ROUND(CB:CB* CC:CC, 2) -> 29.08 | CE24: =ROUND( 1 - ( (D:D * 0.25) + (E:E* 0.2) + (F:F* 0.15) + (G:G* 0.1) ) * AQ:AQ, 3 ) -> 0.8 | CF24: =ROUND( CD:CD* CE:CE, 2 ) -> 23.26 | CG24: =RANK(CF24,CF:CF) -> 137
A25: 604535 | B25: Nitish Rana | C25: Batsman | D25: 1 | E25: 0 | F25: 0 | G25: 0 | H25: 16 | I25: 22 | J25: =ROUND((K25 - MIN($K$2:$K$98)) / (MAX($K$2:$K$98) - MIN($K$2:$K$98)), 1) -> 0.3 | K25: 455 | L25: 0.2 | M25: 0 | N25: Middle | O25: 2 | P25: India | Q25: 0 | R25: 29 | S25: 75 | T25: 30.33 | U25: =ROUND((T25 - MIN(T$2:T$98)) / (MAX(T$2:T$98) - MIN(T$2:T$98)), 1) -> 0.5 | V25: 139.14 | W25: =ROUND((V25 - MIN(V$2:V$98)) / (MAX(V$2:V$98) - MIN(V$2:V$98)), 1) -> 0.6 | X25: 44 | Y25: 21 | Z25: 0 | AA25: 3 | AB25: 8 | AC25: =IF(AB25>AD25, 3,IF(AB25<AD25, 1, 2)) -> 3 | AD25: 1 | AE25: 0.6 | AF25: 0.015 | AG25: 6.5 | AH25: 0.209 | AI25: 65 | AJ25: =ROUND((AI25 - MIN(AI$2:AI$98)) / (MAX(AI$2:AI$98) - MIN(AI$2:AI$98)), 1) -> 0.8 | AK25: 0 | AL25: 0 | AM25: 0 | AN25: 0 | AO25: =ROUND((AP25 - MIN($AP$2:$AP2073)) / (MAX($AP$2:$AP2073) - MIN($AP$2:$AP2073)), 1) -> 0 | AP25: 0 | AQ25: =ROUND((AR25 - MIN($AR$2:$AR2073)) / (MAX($AR$2:$AR2073) - MIN($AR$2:$AR2073)), 1) -> 0.3 | AR25: 3.5 | AS25: 0 | AT25: 0 | AU25: 0 | AV25: 0 | AW25: 35 | AX25: 0.4 | AY25: 0 | AZ25: =(AP25 - MIN($AP$2:$AP$964)) / (MAX($AP$2:$AP$964) - MIN($AP$2:$AP$964)) -> 0 | BA25: 0 | BB25: 0 | BC25: 0 | BD25: 0 | BE25: 6.5 | BF25: =ROUND((BE25 - MIN(BE$2:BE$174)) / (MAX(BE$2:BE$174) - MIN(BE$2:BE$174)), 1) -> 0.1 | BG25: =IF(AND(K25>=800,V25>=145),3,IF(K25>=400,1,2)) -> 1 | BH25: 7 | BI25: =ROUND((BH25 - MIN(BH$2:BH$174)) / (MAX(BH$2:BH$174) - MIN(BH$2:BH$174)), 1) -> 0.3 | BJ25: 7 | BK25: 0.71 | BL25: 7 | BM25: 0.33 | BN25: 0 | BO25: 0 | BP25: =ROUND((0.35 * L25) + (0.25 * W25) + (0.15 * U25) + (0.15 * BF25) + (0.1 * AJ25), 1) -> 0.4 | BQ25: 0 | BR25: 0 | BS25: =(0.45*L25 + 0.35*M25 + 0.12*AJ25 + 0.08*BF25) * (1 - BR25) -> 0.194 | BT25: 0 | BU25: 0 | BV25: 50.35 | BW25: 0.06 | BX25: =D25 * ( BP25*0.4 + L25*0.25 + W25*0.15 + AX25*0.1 + BF25*0.1 ) * 100 -> 35 | BY25: =E:E*(BQ:BQ*0.35+AT:AT*0.3+AV:AV*0.15+AN:AN*0.1+AO:AO*0.1)*100 -> 0 | BZ25: =ROUND(IF(N(F25)=1, MAX(0, ( (N(BN25)/18)*0.6 + (N(BF25)/10)*0.25 + N(AX25)*0.15 ) * 100 ), 0 ),3) -> 0 | CA25: =ROUND(G:G*(BO:BO*0.45+AZ:AZ*0.3+BB:BB*0.15+BF:BF*0.1)*100,3) -> 0 | CB25: =BX:BX+BY:BY+BZ:BZ + CA:CA -> 35 | CC25: =ROUND(0.7 + (BR:BR* 0.2) + (BS:BS * 0.1),3) -> 0.719 | CD25: =ROUND(CB:CB* CC:CC, 2) -> 25.17 | CE25: =ROUND( 1 - ( (D:D * 0.25) + (E:E* 0.2) + (F:F* 0.15) + (G:G* 0.1) ) * AQ:AQ, 3 ) -> 0.925 | CF25: =ROUND( CD:CD* CE:CE, 2 ) -> 23.28 | CG25: =RANK(CF25,CF:CF) -> 136
